2020-02-29 23:19:05,218 - [testcase_audit.py-->line:80] - INFO: 登录用例测试通过
2020-02-29 23:19:05,406 - [testcase_audit.py-->line:80] - INFO: 审核通过用例测试通过
2020-02-29 23:19:05,590 - [testcase_audit.py-->line:80] - INFO: 审核不通过用例测试通过
2020-02-29 23:19:05,758 - [testcase_audit.py-->line:83] - ERROR: 项目不待审核状态用例测试不通过
2020-02-29 23:19:05,758 - [testcase_audit.py-->line:84] - ERROR: 2 != 0
Traceback (most recent call last):
  File "D:\untitled\withdraw_interface\testcase\testcase_audit.py", line 77, in testcase_audit
    self.assertEqual(expected['code'],res_info['code'])
  File "D:\python36\lib\unittest\case.py", line 820, in assertEqual
    assertion_func(first, second, msg=msg)
  File "D:\python36\lib\unittest\case.py", line 813, in _baseAssertEqual
    raise self.failureException(msg)
AssertionError: 2 != 0
2020-02-29 23:19:06,121 - [testcase_audit.py-->line:83] - ERROR: 参数approved_or_not非法用例测试不通过
2020-02-29 23:19:06,122 - [testcase_audit.py-->line:84] - ERROR: 1004 != 0
Traceback (most recent call last):
  File "D:\untitled\withdraw_interface\testcase\testcase_audit.py", line 77, in testcase_audit
    self.assertEqual(expected['code'],res_info['code'])
  File "D:\python36\lib\unittest\case.py", line 820, in assertEqual
    assertion_func(first, second, msg=msg)
  File "D:\python36\lib\unittest\case.py", line 813, in _baseAssertEqual
    raise self.failureException(msg)
AssertionError: 1004 != 0
2020-02-29 23:19:06,289 - [testcase_audit.py-->line:83] - ERROR: 项目为空用例测试不通过
2020-02-29 23:19:06,289 - [testcase_audit.py-->line:84] - ERROR: 1004 != 0
Traceback (most recent call last):
  File "D:\untitled\withdraw_interface\testcase\testcase_audit.py", line 77, in testcase_audit
    self.assertEqual(expected['code'],res_info['code'])
  File "D:\python36\lib\unittest\case.py", line 820, in assertEqual
    assertion_func(first, second, msg=msg)
  File "D:\python36\lib\unittest\case.py", line 813, in _baseAssertEqual
    raise self.failureException(msg)
AssertionError: 1004 != 0
2020-02-29 23:19:06,500 - [testcase_audit.py-->line:83] - ERROR: 项目不存在用例测试不通过
2020-02-29 23:19:06,500 - [testcase_audit.py-->line:84] - ERROR: 1004 != 0
Traceback (most recent call last):
  File "D:\untitled\withdraw_interface\testcase\testcase_audit.py", line 77, in testcase_audit
    self.assertEqual(expected['code'],res_info['code'])
  File "D:\python36\lib\unittest\case.py", line 820, in assertEqual
    assertion_func(first, second, msg=msg)
  File "D:\python36\lib\unittest\case.py", line 813, in _baseAssertEqual
    raise self.failureException(msg)
AssertionError: 1004 != 0
2020-03-01 10:17:17,046 - [testcase_audit.py-->line:85] - INFO: 登录用例测试通过
2020-03-01 10:17:17,421 - [testcase_audit.py-->line:85] - INFO: 审核通过用例测试通过
2020-03-01 10:17:17,591 - [testcase_audit.py-->line:85] - INFO: 审核不通过用例测试通过
2020-03-01 10:17:17,773 - [testcase_audit.py-->line:88] - ERROR: 项目不待审核状态用例测试不通过
2020-03-01 10:17:17,773 - [testcase_audit.py-->line:89] - ERROR: 2 != 0
Traceback (most recent call last):
  File "D:\untitled\withdraw_interface\testcase\testcase_audit.py", line 82, in testcase_audit
    self.assertEqual(expected['code'],res_info['code'])
  File "D:\python36\lib\unittest\case.py", line 820, in assertEqual
    assertion_func(first, second, msg=msg)
  File "D:\python36\lib\unittest\case.py", line 813, in _baseAssertEqual
    raise self.failureException(msg)
AssertionError: 2 != 0
2020-03-01 10:17:17,939 - [testcase_audit.py-->line:88] - ERROR: 参数approved_or_not非法用例测试不通过
2020-03-01 10:17:17,939 - [testcase_audit.py-->line:89] - ERROR: 1004 != 0
Traceback (most recent call last):
  File "D:\untitled\withdraw_interface\testcase\testcase_audit.py", line 82, in testcase_audit
    self.assertEqual(expected['code'],res_info['code'])
  File "D:\python36\lib\unittest\case.py", line 820, in assertEqual
    assertion_func(first, second, msg=msg)
  File "D:\python36\lib\unittest\case.py", line 813, in _baseAssertEqual
    raise self.failureException(msg)
AssertionError: 1004 != 0
2020-03-01 10:17:18,226 - [testcase_audit.py-->line:88] - ERROR: 项目为空用例测试不通过
2020-03-01 10:17:18,226 - [testcase_audit.py-->line:89] - ERROR: 1004 != 0
Traceback (most recent call last):
  File "D:\untitled\withdraw_interface\testcase\testcase_audit.py", line 82, in testcase_audit
    self.assertEqual(expected['code'],res_info['code'])
  File "D:\python36\lib\unittest\case.py", line 820, in assertEqual
    assertion_func(first, second, msg=msg)
  File "D:\python36\lib\unittest\case.py", line 813, in _baseAssertEqual
    raise self.failureException(msg)
AssertionError: 1004 != 0
2020-03-01 10:17:18,410 - [testcase_audit.py-->line:88] - ERROR: 项目不存在用例测试不通过
2020-03-01 10:17:18,410 - [testcase_audit.py-->line:89] - ERROR: 1004 != 0
Traceback (most recent call last):
  File "D:\untitled\withdraw_interface\testcase\testcase_audit.py", line 82, in testcase_audit
    self.assertEqual(expected['code'],res_info['code'])
  File "D:\python36\lib\unittest\case.py", line 820, in assertEqual
    assertion_func(first, second, msg=msg)
  File "D:\python36\lib\unittest\case.py", line 813, in _baseAssertEqual
    raise self.failureException(msg)
AssertionError: 1004 != 0
2020-03-01 10:28:10,935 - [testcase_audit.py-->line:87] - INFO: 登录用例测试通过
2020-03-01 10:28:11,142 - [testcase_audit.py-->line:87] - INFO: 审核通过用例测试通过
2020-03-01 10:28:11,324 - [testcase_audit.py-->line:87] - INFO: 审核不通过用例测试通过
2020-03-01 10:28:11,511 - [testcase_audit.py-->line:87] - INFO: 项目不待审核状态用例测试通过
2020-03-01 10:28:11,715 - [testcase_audit.py-->line:90] - ERROR: 参数approved_or_not非法用例测试不通过
2020-03-01 10:28:11,716 - [testcase_audit.py-->line:91] - ERROR: 1004 != 0
Traceback (most recent call last):
  File "D:\untitled\withdraw_interface\testcase\testcase_audit.py", line 84, in testcase_audit
    self.assertEqual(expected['code'],res_info['code'])
  File "D:\python36\lib\unittest\case.py", line 820, in assertEqual
    assertion_func(first, second, msg=msg)
  File "D:\python36\lib\unittest\case.py", line 813, in _baseAssertEqual
    raise self.failureException(msg)
AssertionError: 1004 != 0
2020-03-01 10:28:12,078 - [testcase_audit.py-->line:90] - ERROR: 项目为空用例测试不通过
2020-03-01 10:28:12,078 - [testcase_audit.py-->line:91] - ERROR: 1004 != 0
Traceback (most recent call last):
  File "D:\untitled\withdraw_interface\testcase\testcase_audit.py", line 84, in testcase_audit
    self.assertEqual(expected['code'],res_info['code'])
  File "D:\python36\lib\unittest\case.py", line 820, in assertEqual
    assertion_func(first, second, msg=msg)
  File "D:\python36\lib\unittest\case.py", line 813, in _baseAssertEqual
    raise self.failureException(msg)
AssertionError: 1004 != 0
2020-03-01 10:28:12,283 - [testcase_audit.py-->line:90] - ERROR: 项目不存在用例测试不通过
2020-03-01 10:28:12,283 - [testcase_audit.py-->line:91] - ERROR: 1004 != 0
Traceback (most recent call last):
  File "D:\untitled\withdraw_interface\testcase\testcase_audit.py", line 84, in testcase_audit
    self.assertEqual(expected['code'],res_info['code'])
  File "D:\python36\lib\unittest\case.py", line 820, in assertEqual
    assertion_func(first, second, msg=msg)
  File "D:\python36\lib\unittest\case.py", line 813, in _baseAssertEqual
    raise self.failureException(msg)
AssertionError: 1004 != 0
2020-03-01 10:33:40,371 - [testcase_audit.py-->line:88] - INFO: 登录用例测试通过
2020-03-01 10:33:40,588 - [testcase_audit.py-->line:88] - INFO: 审核通过用例测试通过
2020-03-01 10:33:40,768 - [testcase_audit.py-->line:88] - INFO: 审核不通过用例测试通过
2020-03-01 10:33:40,938 - [testcase_audit.py-->line:88] - INFO: 项目不待审核状态用例测试通过
2020-03-01 10:33:41,108 - [testcase_audit.py-->line:91] - ERROR: 参数approved_or_not非法用例测试不通过
2020-03-01 10:33:41,108 - [testcase_audit.py-->line:92] - ERROR: 1004 != 0
Traceback (most recent call last):
  File "D:\untitled\withdraw_interface\testcase\testcase_audit.py", line 85, in testcase_audit
    self.assertEqual(expected['code'],res_info['code'])
  File "D:\python36\lib\unittest\case.py", line 820, in assertEqual
    assertion_func(first, second, msg=msg)
  File "D:\python36\lib\unittest\case.py", line 813, in _baseAssertEqual
    raise self.failureException(msg)
AssertionError: 1004 != 0
2020-03-01 10:33:41,280 - [testcase_audit.py-->line:91] - ERROR: 项目为空用例测试不通过
2020-03-01 10:33:41,280 - [testcase_audit.py-->line:92] - ERROR: 1004 != 0
Traceback (most recent call last):
  File "D:\untitled\withdraw_interface\testcase\testcase_audit.py", line 85, in testcase_audit
    self.assertEqual(expected['code'],res_info['code'])
  File "D:\python36\lib\unittest\case.py", line 820, in assertEqual
    assertion_func(first, second, msg=msg)
  File "D:\python36\lib\unittest\case.py", line 813, in _baseAssertEqual
    raise self.failureException(msg)
AssertionError: 1004 != 0
2020-03-01 10:33:41,450 - [testcase_audit.py-->line:91] - ERROR: 项目不存在用例测试不通过
2020-03-01 10:33:41,450 - [testcase_audit.py-->line:92] - ERROR: 1004 != 0
Traceback (most recent call last):
  File "D:\untitled\withdraw_interface\testcase\testcase_audit.py", line 85, in testcase_audit
    self.assertEqual(expected['code'],res_info['code'])
  File "D:\python36\lib\unittest\case.py", line 820, in assertEqual
    assertion_func(first, second, msg=msg)
  File "D:\python36\lib\unittest\case.py", line 813, in _baseAssertEqual
    raise self.failureException(msg)
AssertionError: 1004 != 0
2020-03-01 10:41:50,147 - [testcase_add.py-->line:61] - INFO: 登录用例测试通过
2020-03-01 10:41:50,482 - [testcase_add.py-->line:61] - INFO: 添加成功用例测试通过
2020-03-01 10:41:50,606 - [testcase_add.py-->line:61] - INFO: 添加成功_借款期限类型2用例测试通过
2020-03-01 10:41:50,730 - [testcase_add.py-->line:64] - ERROR: 添加不成功_标题为int用例测试不通过
2020-03-01 10:41:50,730 - [testcase_add.py-->line:65] - ERROR: 2 != 0
Traceback (most recent call last):
  File "D:\untitled\withdraw_interface\testcase\testcase_add.py", line 58, in testcase_add
    self.assertEqual(expected['code'],res_info['code'])
  File "D:\python36\lib\unittest\case.py", line 820, in assertEqual
    assertion_func(first, second, msg=msg)
  File "D:\python36\lib\unittest\case.py", line 813, in _baseAssertEqual
    raise self.failureException(msg)
AssertionError: 2 != 0
2020-03-01 10:41:50,877 - [testcase_add.py-->line:64] - ERROR: 添加不成功_借款金额str用例测试不通过
2020-03-01 10:41:50,877 - [testcase_add.py-->line:65] - ERROR: 'OK' != 'JSON parse error: Cannot deserialize valu[366 chars]t"])'
- OK
+ JSON parse error: Cannot deserialize value of type `java.lang.Double` from String "strstr": not a valid Double value; nested exception is com.fasterxml.jackson.databind.exc.InvalidFormatException: Cannot deserialize value of type `java.lang.Double` from String "strstr": not a valid Double value
 at [Source: (PushbackInputStream); line: 1, column: 137] (through reference chain: com.lemon.pojo.Loan["amount"])
Traceback (most recent call last):
  File "D:\untitled\withdraw_interface\testcase\testcase_add.py", line 59, in testcase_add
    self.assertEqual(expected['msg'],res_info['msg'])
  File "D:\python36\lib\unittest\case.py", line 820, in assertEqual
    assertion_func(first, second, msg=msg)
  File "D:\python36\lib\unittest\case.py", line 1193, in assertMultiLineEqual
    self.fail(self._formatMessage(msg, standardMsg))
  File "D:\python36\lib\unittest\case.py", line 665, in fail
    raise self.failureException(msg)
AssertionError: 'OK' != 'JSON parse error: Cannot deserialize valu[366 chars]t"])'
- OK
+ JSON parse error: Cannot deserialize value of type `java.lang.Double` from String "strstr": not a valid Double value; nested exception is com.fasterxml.jackson.databind.exc.InvalidFormatException: Cannot deserialize value of type `java.lang.Double` from String "strstr": not a valid Double value
 at [Source: (PushbackInputStream); line: 1, column: 137] (through reference chain: com.lemon.pojo.Loan["amount"])

2020-03-01 10:41:50,999 - [testcase_add.py-->line:64] - ERROR: 添加不成功_年利率str用例测试不通过
2020-03-01 10:41:50,999 - [testcase_add.py-->line:65] - ERROR: 'OK' != 'JSON parse error: Cannot deserialize valu[362 chars]e"])'
- OK
+ JSON parse error: Cannot deserialize value of type `java.lang.Double` from String "年利率": not a valid Double value; nested exception is com.fasterxml.jackson.databind.exc.InvalidFormatException: Cannot deserialize value of type `java.lang.Double` from String "年利率": not a valid Double value
 at [Source: (PushbackInputStream); line: 1, column: 81] (through reference chain: com.lemon.pojo.Loan["loan_rate"])
Traceback (most recent call last):
  File "D:\untitled\withdraw_interface\testcase\testcase_add.py", line 59, in testcase_add
    self.assertEqual(expected['msg'],res_info['msg'])
  File "D:\python36\lib\unittest\case.py", line 820, in assertEqual
    assertion_func(first, second, msg=msg)
  File "D:\python36\lib\unittest\case.py", line 1193, in assertMultiLineEqual
    self.fail(self._formatMessage(msg, standardMsg))
  File "D:\python36\lib\unittest\case.py", line 665, in fail
    raise self.failureException(msg)
AssertionError: 'OK' != 'JSON parse error: Cannot deserialize valu[362 chars]e"])'
- OK
+ JSON parse error: Cannot deserialize value of type `java.lang.Double` from String "年利率": not a valid Double value; nested exception is com.fasterxml.jackson.databind.exc.InvalidFormatException: Cannot deserialize value of type `java.lang.Double` from String "年利率": not a valid Double value
 at [Source: (PushbackInputStream); line: 1, column: 81] (through reference chain: com.lemon.pojo.Loan["loan_rate"])

2020-03-01 10:41:51,122 - [testcase_add.py-->line:64] - ERROR: 添加不成功_借款期限str用例测试不通过
2020-03-01 10:41:51,123 - [testcase_add.py-->line:65] - ERROR: 2 != 0
Traceback (most recent call last):
  File "D:\untitled\withdraw_interface\testcase\testcase_add.py", line 58, in testcase_add
    self.assertEqual(expected['code'],res_info['code'])
  File "D:\python36\lib\unittest\case.py", line 820, in assertEqual
    assertion_func(first, second, msg=msg)
  File "D:\python36\lib\unittest\case.py", line 813, in _baseAssertEqual
    raise self.failureException(msg)
AssertionError: 2 != 0
2020-03-01 10:41:51,280 - [testcase_add.py-->line:61] - INFO: 添加不成功_借款期限类型非1或2用例测试通过
2020-03-01 10:41:51,413 - [testcase_add.py-->line:61] - INFO: 添加不成功_竞标天数非法用例测试通过
2020-03-01 10:41:57,123 - [testcase_audit.py-->line:87] - INFO: 登录用例测试通过
2020-03-01 10:41:57,327 - [testcase_audit.py-->line:87] - INFO: 审核通过用例测试通过
2020-03-01 10:41:57,504 - [testcase_audit.py-->line:87] - INFO: 审核不通过用例测试通过
2020-03-01 10:41:57,684 - [testcase_audit.py-->line:87] - INFO: 项目不待审核状态用例测试通过
2020-03-01 10:41:57,876 - [testcase_audit.py-->line:90] - ERROR: 参数approved_or_not非法用例测试不通过
2020-03-01 10:41:57,877 - [testcase_audit.py-->line:91] - ERROR: 1004 != 0
Traceback (most recent call last):
  File "D:\untitled\withdraw_interface\testcase\testcase_audit.py", line 84, in testcase_audit
    self.assertEqual(expected['code'],res_info['code'])
  File "D:\python36\lib\unittest\case.py", line 820, in assertEqual
    assertion_func(first, second, msg=msg)
  File "D:\python36\lib\unittest\case.py", line 813, in _baseAssertEqual
    raise self.failureException(msg)
AssertionError: 1004 != 0
2020-03-01 10:41:58,045 - [testcase_audit.py-->line:90] - ERROR: 项目为空用例测试不通过
2020-03-01 10:41:58,045 - [testcase_audit.py-->line:91] - ERROR: 1004 != 0
Traceback (most recent call last):
  File "D:\untitled\withdraw_interface\testcase\testcase_audit.py", line 84, in testcase_audit
    self.assertEqual(expected['code'],res_info['code'])
  File "D:\python36\lib\unittest\case.py", line 820, in assertEqual
    assertion_func(first, second, msg=msg)
  File "D:\python36\lib\unittest\case.py", line 813, in _baseAssertEqual
    raise self.failureException(msg)
AssertionError: 1004 != 0
2020-03-01 10:41:58,226 - [testcase_audit.py-->line:90] - ERROR: 项目不存在用例测试不通过
2020-03-01 10:41:58,226 - [testcase_audit.py-->line:91] - ERROR: 1004 != 0
Traceback (most recent call last):
  File "D:\untitled\withdraw_interface\testcase\testcase_audit.py", line 84, in testcase_audit
    self.assertEqual(expected['code'],res_info['code'])
  File "D:\python36\lib\unittest\case.py", line 820, in assertEqual
    assertion_func(first, second, msg=msg)
  File "D:\python36\lib\unittest\case.py", line 813, in _baseAssertEqual
    raise self.failureException(msg)
AssertionError: 1004 != 0
2020-03-01 10:42:00,214 - [testcase_withdraw.py-->line:61] - INFO: 登录用例测试通过
2020-03-01 10:42:00,525 - [testcase_withdraw.py-->line:64] - ERROR: 提现成功用例测试不通过
2020-03-01 10:42:00,525 - [testcase_withdraw.py-->line:65] - ERROR: Decimal('10000') != Decimal('0.00')
Traceback (most recent call last):
  File "D:\untitled\withdraw_interface\testcase\testcase_withdraw.py", line 57, in testcase_withdraw
    self.assertEqual(Decimal(str(data['amount'])),(leave_amount_start-leave_amount_end))
  File "D:\python36\lib\unittest\case.py", line 820, in assertEqual
    assertion_func(first, second, msg=msg)
  File "D:\python36\lib\unittest\case.py", line 813, in _baseAssertEqual
    raise self.failureException(msg)
AssertionError: Decimal('10000') != Decimal('0.00')
2020-03-01 10:42:00,670 - [testcase_withdraw.py-->line:61] - INFO: 提现不成功-MemberId为空用例测试通过
2020-03-01 10:42:00,810 - [testcase_withdraw.py-->line:61] - INFO: 提现不成功-Amount为空用例测试通过
2020-03-01 10:42:00,927 - [testcase_withdraw.py-->line:61] - INFO: 提现不成功-Amount为负值用例测试通过
2020-03-01 10:42:01,044 - [testcase_withdraw.py-->line:61] - INFO: 提现不成功-Amount大于500000用例测试通过
2020-03-01 10:42:01,158 - [testcase_withdraw.py-->line:61] - INFO: 提现不成功-Amount的小数位数多于2位用例测试通过
2020-03-01 10:42:01,475 - [testcase_withdraw.py-->line:64] - ERROR: 提现成功-Amount的小数位数1位用例测试不通过
2020-03-01 10:42:01,475 - [testcase_withdraw.py-->line:65] - ERROR: Decimal('400000.1') != Decimal('0.00')
Traceback (most recent call last):
  File "D:\untitled\withdraw_interface\testcase\testcase_withdraw.py", line 57, in testcase_withdraw
    self.assertEqual(Decimal(str(data['amount'])),(leave_amount_start-leave_amount_end))
  File "D:\python36\lib\unittest\case.py", line 820, in assertEqual
    assertion_func(first, second, msg=msg)
  File "D:\python36\lib\unittest\case.py", line 813, in _baseAssertEqual
    raise self.failureException(msg)
AssertionError: Decimal('400000.1') != Decimal('0.00')
2020-03-01 10:42:01,778 - [testcase_withdraw.py-->line:64] - ERROR: 提现成功-Amount的小数位数2位用例测试不通过
2020-03-01 10:42:01,778 - [testcase_withdraw.py-->line:65] - ERROR: Decimal('400000.09') != Decimal('0.00')
Traceback (most recent call last):
  File "D:\untitled\withdraw_interface\testcase\testcase_withdraw.py", line 57, in testcase_withdraw
    self.assertEqual(Decimal(str(data['amount'])),(leave_amount_start-leave_amount_end))
  File "D:\python36\lib\unittest\case.py", line 820, in assertEqual
    assertion_func(first, second, msg=msg)
  File "D:\python36\lib\unittest\case.py", line 813, in _baseAssertEqual
    raise self.failureException(msg)
AssertionError: Decimal('400000.09') != Decimal('0.00')
2020-03-01 16:34:32,975 - [testcase_invest.py-->line:87] - INFO: 登录用例测试通过
2020-03-01 16:34:33,171 - [testcase_invest.py-->line:90] - ERROR: 投资不通过_投资项目非竞标状态用例测试不通过
2020-03-01 16:34:33,171 - [testcase_invest.py-->line:91] - ERROR: 1004 != 0
Traceback (most recent call last):
  File "D:\untitled\withdraw_interface\testcase\testcase_invest.py", line 84, in test_invest
    self.assertEqual(expected['code'],res_info['code'])
  File "D:\python36\lib\unittest\case.py", line 820, in assertEqual
    assertion_func(first, second, msg=msg)
  File "D:\python36\lib\unittest\case.py", line 813, in _baseAssertEqual
    raise self.failureException(msg)
AssertionError: 1004 != 0
2020-03-01 16:34:33,441 - [testcase_invest.py-->line:87] - INFO: 投资通过用例测试通过
2020-03-01 16:34:33,645 - [testcase_invest.py-->line:87] - INFO: 投资不通过_投资费非100整数用例测试通过
2020-03-01 16:34:33,816 - [testcase_invest.py-->line:87] - INFO: 投资不通过_投资费大于项目费用用例测试通过
2020-03-01 16:34:34,010 - [testcase_invest.py-->line:90] - ERROR: 投资不通过用例测试不通过
2020-03-01 16:34:34,010 - [testcase_invest.py-->line:91] - ERROR: 1004 != 0
Traceback (most recent call last):
  File "D:\untitled\withdraw_interface\testcase\testcase_invest.py", line 84, in test_invest
    self.assertEqual(expected['code'],res_info['code'])
  File "D:\python36\lib\unittest\case.py", line 820, in assertEqual
    assertion_func(first, second, msg=msg)
  File "D:\python36\lib\unittest\case.py", line 813, in _baseAssertEqual
    raise self.failureException(msg)
AssertionError: 1004 != 0
2020-03-01 16:34:34,185 - [testcase_invest.py-->line:90] - ERROR: 投资不通过用例测试不通过
2020-03-01 16:34:34,185 - [testcase_invest.py-->line:91] - ERROR: 1004 != 0
Traceback (most recent call last):
  File "D:\untitled\withdraw_interface\testcase\testcase_invest.py", line 84, in test_invest
    self.assertEqual(expected['code'],res_info['code'])
  File "D:\python36\lib\unittest\case.py", line 820, in assertEqual
    assertion_func(first, second, msg=msg)
  File "D:\python36\lib\unittest\case.py", line 813, in _baseAssertEqual
    raise self.failureException(msg)
AssertionError: 1004 != 0
2020-03-01 20:10:03,986 - [testcase_add.py-->line:61] - INFO: 登录用例测试通过
2020-03-01 20:10:04,551 - [testcase_add.py-->line:61] - INFO: 添加成功用例测试通过
2020-03-01 20:10:04,677 - [testcase_add.py-->line:61] - INFO: 添加成功_借款期限类型2用例测试通过
2020-03-01 20:10:04,806 - [testcase_add.py-->line:64] - ERROR: 添加不成功_标题为int用例测试不通过
2020-03-01 20:10:04,806 - [testcase_add.py-->line:65] - ERROR: 2 != 0
Traceback (most recent call last):
  File "D:\untitled\withdraw_interface\testcase\testcase_add.py", line 58, in testcase_add
    self.assertEqual(expected['code'],res_info['code'])
  File "D:\python36\lib\unittest\case.py", line 820, in assertEqual
    assertion_func(first, second, msg=msg)
  File "D:\python36\lib\unittest\case.py", line 813, in _baseAssertEqual
    raise self.failureException(msg)
AssertionError: 2 != 0
2020-03-01 20:10:05,133 - [testcase_add.py-->line:64] - ERROR: 添加不成功_借款金额str用例测试不通过
2020-03-01 20:10:05,134 - [testcase_add.py-->line:65] - ERROR: 'OK' != 'JSON parse error: Cannot deserialize valu[365 chars]t"])'
- OK
+ JSON parse error: Cannot deserialize value of type `java.lang.Double` from String "strstr": not a valid Double value; nested exception is com.fasterxml.jackson.databind.exc.InvalidFormatException: Cannot deserialize value of type `java.lang.Double` from String "strstr": not a valid Double value
 at [Source: (PushbackInputStream); line: 1, column: 12] (through reference chain: com.lemon.pojo.Loan["amount"])
Traceback (most recent call last):
  File "D:\untitled\withdraw_interface\testcase\testcase_add.py", line 59, in testcase_add
    self.assertEqual(expected['msg'],res_info['msg'])
  File "D:\python36\lib\unittest\case.py", line 820, in assertEqual
    assertion_func(first, second, msg=msg)
  File "D:\python36\lib\unittest\case.py", line 1193, in assertMultiLineEqual
    self.fail(self._formatMessage(msg, standardMsg))
  File "D:\python36\lib\unittest\case.py", line 665, in fail
    raise self.failureException(msg)
AssertionError: 'OK' != 'JSON parse error: Cannot deserialize valu[365 chars]t"])'
- OK
+ JSON parse error: Cannot deserialize value of type `java.lang.Double` from String "strstr": not a valid Double value; nested exception is com.fasterxml.jackson.databind.exc.InvalidFormatException: Cannot deserialize value of type `java.lang.Double` from String "strstr": not a valid Double value
 at [Source: (PushbackInputStream); line: 1, column: 12] (through reference chain: com.lemon.pojo.Loan["amount"])

2020-03-01 20:10:05,415 - [testcase_add.py-->line:64] - ERROR: 添加不成功_年利率str用例测试不通过
2020-03-01 20:10:05,416 - [testcase_add.py-->line:65] - ERROR: 'OK' != 'JSON parse error: Cannot deserialize valu[362 chars]e"])'
- OK
+ JSON parse error: Cannot deserialize value of type `java.lang.Double` from String "年利率": not a valid Double value; nested exception is com.fasterxml.jackson.databind.exc.InvalidFormatException: Cannot deserialize value of type `java.lang.Double` from String "年利率": not a valid Double value
 at [Source: (PushbackInputStream); line: 1, column: 33] (through reference chain: com.lemon.pojo.Loan["loan_rate"])
Traceback (most recent call last):
  File "D:\untitled\withdraw_interface\testcase\testcase_add.py", line 59, in testcase_add
    self.assertEqual(expected['msg'],res_info['msg'])
  File "D:\python36\lib\unittest\case.py", line 820, in assertEqual
    assertion_func(first, second, msg=msg)
  File "D:\python36\lib\unittest\case.py", line 1193, in assertMultiLineEqual
    self.fail(self._formatMessage(msg, standardMsg))
  File "D:\python36\lib\unittest\case.py", line 665, in fail
    raise self.failureException(msg)
AssertionError: 'OK' != 'JSON parse error: Cannot deserialize valu[362 chars]e"])'
- OK
+ JSON parse error: Cannot deserialize value of type `java.lang.Double` from String "年利率": not a valid Double value; nested exception is com.fasterxml.jackson.databind.exc.InvalidFormatException: Cannot deserialize value of type `java.lang.Double` from String "年利率": not a valid Double value
 at [Source: (PushbackInputStream); line: 1, column: 33] (through reference chain: com.lemon.pojo.Loan["loan_rate"])

2020-03-01 20:10:05,585 - [testcase_add.py-->line:64] - ERROR: 添加不成功_借款期限str用例测试不通过
2020-03-01 20:10:05,585 - [testcase_add.py-->line:65] - ERROR: 2 != 0
Traceback (most recent call last):
  File "D:\untitled\withdraw_interface\testcase\testcase_add.py", line 58, in testcase_add
    self.assertEqual(expected['code'],res_info['code'])
  File "D:\python36\lib\unittest\case.py", line 820, in assertEqual
    assertion_func(first, second, msg=msg)
  File "D:\python36\lib\unittest\case.py", line 813, in _baseAssertEqual
    raise self.failureException(msg)
AssertionError: 2 != 0
2020-03-01 20:10:05,711 - [testcase_add.py-->line:61] - INFO: 添加不成功_借款期限类型非1或2用例测试通过
2020-03-01 20:10:05,860 - [testcase_add.py-->line:61] - INFO: 添加不成功_竞标天数非法用例测试通过
2020-03-01 20:10:08,206 - [testcase_audit.py-->line:87] - INFO: 登录用例测试通过
2020-03-01 20:10:08,398 - [testcase_audit.py-->line:87] - INFO: 审核通过用例测试通过
2020-03-01 20:10:08,574 - [testcase_audit.py-->line:87] - INFO: 审核不通过用例测试通过
2020-03-01 20:10:08,756 - [testcase_audit.py-->line:87] - INFO: 项目不待审核状态用例测试通过
2020-03-01 20:10:08,932 - [testcase_audit.py-->line:90] - ERROR: 参数approved_or_not非法用例测试不通过
2020-03-01 20:10:08,932 - [testcase_audit.py-->line:91] - ERROR: 1004 != 0
Traceback (most recent call last):
  File "D:\untitled\withdraw_interface\testcase\testcase_audit.py", line 84, in testcase_audit
    self.assertEqual(expected['code'],res_info['code'])
  File "D:\python36\lib\unittest\case.py", line 820, in assertEqual
    assertion_func(first, second, msg=msg)
  File "D:\python36\lib\unittest\case.py", line 813, in _baseAssertEqual
    raise self.failureException(msg)
AssertionError: 1004 != 0
2020-03-01 20:10:09,140 - [testcase_audit.py-->line:90] - ERROR: 项目为空用例测试不通过
2020-03-01 20:10:09,141 - [testcase_audit.py-->line:91] - ERROR: 1004 != 0
Traceback (most recent call last):
  File "D:\untitled\withdraw_interface\testcase\testcase_audit.py", line 84, in testcase_audit
    self.assertEqual(expected['code'],res_info['code'])
  File "D:\python36\lib\unittest\case.py", line 820, in assertEqual
    assertion_func(first, second, msg=msg)
  File "D:\python36\lib\unittest\case.py", line 813, in _baseAssertEqual
    raise self.failureException(msg)
AssertionError: 1004 != 0
2020-03-01 20:10:09,319 - [testcase_audit.py-->line:90] - ERROR: 项目不存在用例测试不通过
2020-03-01 20:10:09,319 - [testcase_audit.py-->line:91] - ERROR: 1004 != 0
Traceback (most recent call last):
  File "D:\untitled\withdraw_interface\testcase\testcase_audit.py", line 84, in testcase_audit
    self.assertEqual(expected['code'],res_info['code'])
  File "D:\python36\lib\unittest\case.py", line 820, in assertEqual
    assertion_func(first, second, msg=msg)
  File "D:\python36\lib\unittest\case.py", line 813, in _baseAssertEqual
    raise self.failureException(msg)
AssertionError: 1004 != 0
2020-03-01 20:10:11,661 - [testcase_invest.py-->line:92] - INFO: 登录用例测试通过
2020-03-01 20:10:11,829 - [testcase_invest.py-->line:95] - ERROR: 投资不通过_投资项目非竞标状态用例测试不通过
2020-03-01 20:10:11,829 - [testcase_invest.py-->line:96] - ERROR: 1004 != 0
Traceback (most recent call last):
  File "D:\untitled\withdraw_interface\testcase\testcase_invest.py", line 89, in test_invest
    self.assertEqual(expected['code'],res_info['code'])
  File "D:\python36\lib\unittest\case.py", line 820, in assertEqual
    assertion_func(first, second, msg=msg)
  File "D:\python36\lib\unittest\case.py", line 813, in _baseAssertEqual
    raise self.failureException(msg)
AssertionError: 1004 != 0
2020-03-01 20:10:12,030 - [testcase_invest.py-->line:92] - INFO: 投资通过用例测试通过
2020-03-01 20:10:12,225 - [testcase_invest.py-->line:92] - INFO: 投资不通过_投资费非100整数用例测试通过
2020-03-01 20:10:12,394 - [testcase_invest.py-->line:92] - INFO: 投资不通过_投资费大于项目费用用例测试通过
2020-03-01 20:10:12,562 - [testcase_invest.py-->line:95] - ERROR: 投资不通过用例测试不通过
2020-03-01 20:10:12,562 - [testcase_invest.py-->line:96] - ERROR: 1004 != 0
Traceback (most recent call last):
  File "D:\untitled\withdraw_interface\testcase\testcase_invest.py", line 89, in test_invest
    self.assertEqual(expected['code'],res_info['code'])
  File "D:\python36\lib\unittest\case.py", line 820, in assertEqual
    assertion_func(first, second, msg=msg)
  File "D:\python36\lib\unittest\case.py", line 813, in _baseAssertEqual
    raise self.failureException(msg)
AssertionError: 1004 != 0
2020-03-01 20:10:12,734 - [testcase_invest.py-->line:95] - ERROR: 投资不通过用例测试不通过
2020-03-01 20:10:12,734 - [testcase_invest.py-->line:96] - ERROR: 1004 != 0
Traceback (most recent call last):
  File "D:\untitled\withdraw_interface\testcase\testcase_invest.py", line 89, in test_invest
    self.assertEqual(expected['code'],res_info['code'])
  File "D:\python36\lib\unittest\case.py", line 820, in assertEqual
    assertion_func(first, second, msg=msg)
  File "D:\python36\lib\unittest\case.py", line 813, in _baseAssertEqual
    raise self.failureException(msg)
AssertionError: 1004 != 0
2020-03-01 20:10:13,937 - [testcase_withdraw.py-->line:61] - INFO: 登录用例测试通过
2020-03-01 20:10:14,245 - [testcase_withdraw.py-->line:64] - ERROR: 提现成功用例测试不通过
2020-03-01 20:10:14,245 - [testcase_withdraw.py-->line:65] - ERROR: Decimal('10000') != Decimal('0.00')
Traceback (most recent call last):
  File "D:\untitled\withdraw_interface\testcase\testcase_withdraw.py", line 57, in testcase_withdraw
    self.assertEqual(Decimal(str(data['amount'])),(leave_amount_start-leave_amount_end))
  File "D:\python36\lib\unittest\case.py", line 820, in assertEqual
    assertion_func(first, second, msg=msg)
  File "D:\python36\lib\unittest\case.py", line 813, in _baseAssertEqual
    raise self.failureException(msg)
AssertionError: Decimal('10000') != Decimal('0.00')
2020-03-01 20:10:14,398 - [testcase_withdraw.py-->line:61] - INFO: 提现不成功-MemberId为空用例测试通过
2020-03-01 20:10:14,540 - [testcase_withdraw.py-->line:61] - INFO: 提现不成功-Amount为空用例测试通过
2020-03-01 20:10:14,665 - [testcase_withdraw.py-->line:61] - INFO: 提现不成功-Amount为负值用例测试通过
2020-03-01 20:10:14,791 - [testcase_withdraw.py-->line:61] - INFO: 提现不成功-Amount大于500000用例测试通过
2020-03-01 20:10:14,938 - [testcase_withdraw.py-->line:61] - INFO: 提现不成功-Amount的小数位数多于2位用例测试通过
2020-03-01 20:10:15,237 - [testcase_withdraw.py-->line:64] - ERROR: 提现成功-Amount的小数位数1位用例测试不通过
2020-03-01 20:10:15,238 - [testcase_withdraw.py-->line:65] - ERROR: Decimal('400000.1') != Decimal('0.00')
Traceback (most recent call last):
  File "D:\untitled\withdraw_interface\testcase\testcase_withdraw.py", line 57, in testcase_withdraw
    self.assertEqual(Decimal(str(data['amount'])),(leave_amount_start-leave_amount_end))
  File "D:\python36\lib\unittest\case.py", line 820, in assertEqual
    assertion_func(first, second, msg=msg)
  File "D:\python36\lib\unittest\case.py", line 813, in _baseAssertEqual
    raise self.failureException(msg)
AssertionError: Decimal('400000.1') != Decimal('0.00')
2020-03-01 20:10:15,556 - [testcase_withdraw.py-->line:64] - ERROR: 提现成功-Amount的小数位数2位用例测试不通过
2020-03-01 20:10:15,557 - [testcase_withdraw.py-->line:65] - ERROR: Decimal('400000.09') != Decimal('0.00')
Traceback (most recent call last):
  File "D:\untitled\withdraw_interface\testcase\testcase_withdraw.py", line 57, in testcase_withdraw
    self.assertEqual(Decimal(str(data['amount'])),(leave_amount_start-leave_amount_end))
  File "D:\python36\lib\unittest\case.py", line 820, in assertEqual
    assertion_func(first, second, msg=msg)
  File "D:\python36\lib\unittest\case.py", line 813, in _baseAssertEqual
    raise self.failureException(msg)
AssertionError: Decimal('400000.09') != Decimal('0.00')
2020-03-01 20:20:42,101 - [testcase_add.py-->line:61] - INFO: 登录用例测试通过
2020-03-01 20:20:42,430 - [testcase_add.py-->line:61] - INFO: 添加成功用例测试通过
2020-03-01 20:20:42,585 - [testcase_add.py-->line:61] - INFO: 添加成功_借款期限类型2用例测试通过
2020-03-01 20:20:42,742 - [testcase_add.py-->line:64] - ERROR: 添加不成功_标题为int用例测试不通过
2020-03-01 20:20:42,742 - [testcase_add.py-->line:65] - ERROR: 2 != 0
Traceback (most recent call last):
  File "D:\untitled\withdraw_interface\testcase\testcase_add.py", line 58, in testcase_add
    self.assertEqual(expected['code'],res_info['code'])
  File "D:\python36\lib\unittest\case.py", line 820, in assertEqual
    assertion_func(first, second, msg=msg)
  File "D:\python36\lib\unittest\case.py", line 813, in _baseAssertEqual
    raise self.failureException(msg)
AssertionError: 2 != 0
2020-03-01 20:20:42,935 - [testcase_add.py-->line:64] - ERROR: 添加不成功_借款金额str用例测试不通过
2020-03-01 20:20:42,935 - [testcase_add.py-->line:65] - ERROR: 'OK' != 'JSON parse error: Cannot deserialize valu[365 chars]t"])'
- OK
+ JSON parse error: Cannot deserialize value of type `java.lang.Double` from String "strstr": not a valid Double value; nested exception is com.fasterxml.jackson.databind.exc.InvalidFormatException: Cannot deserialize value of type `java.lang.Double` from String "strstr": not a valid Double value
 at [Source: (PushbackInputStream); line: 1, column: 29] (through reference chain: com.lemon.pojo.Loan["amount"])
Traceback (most recent call last):
  File "D:\untitled\withdraw_interface\testcase\testcase_add.py", line 59, in testcase_add
    self.assertEqual(expected['msg'],res_info['msg'])
  File "D:\python36\lib\unittest\case.py", line 820, in assertEqual
    assertion_func(first, second, msg=msg)
  File "D:\python36\lib\unittest\case.py", line 1193, in assertMultiLineEqual
    self.fail(self._formatMessage(msg, standardMsg))
  File "D:\python36\lib\unittest\case.py", line 665, in fail
    raise self.failureException(msg)
AssertionError: 'OK' != 'JSON parse error: Cannot deserialize valu[365 chars]t"])'
- OK
+ JSON parse error: Cannot deserialize value of type `java.lang.Double` from String "strstr": not a valid Double value; nested exception is com.fasterxml.jackson.databind.exc.InvalidFormatException: Cannot deserialize value of type `java.lang.Double` from String "strstr": not a valid Double value
 at [Source: (PushbackInputStream); line: 1, column: 29] (through reference chain: com.lemon.pojo.Loan["amount"])

2020-03-01 20:20:43,061 - [testcase_add.py-->line:64] - ERROR: 添加不成功_年利率str用例测试不通过
2020-03-01 20:20:43,061 - [testcase_add.py-->line:65] - ERROR: 'OK' != 'JSON parse error: Cannot deserialize valu[363 chars]e"])'
- OK
+ JSON parse error: Cannot deserialize value of type `java.lang.Double` from String "年利率": not a valid Double value; nested exception is com.fasterxml.jackson.databind.exc.InvalidFormatException: Cannot deserialize value of type `java.lang.Double` from String "年利率": not a valid Double value
 at [Source: (PushbackInputStream); line: 1, column: 109] (through reference chain: com.lemon.pojo.Loan["loan_rate"])
Traceback (most recent call last):
  File "D:\untitled\withdraw_interface\testcase\testcase_add.py", line 59, in testcase_add
    self.assertEqual(expected['msg'],res_info['msg'])
  File "D:\python36\lib\unittest\case.py", line 820, in assertEqual
    assertion_func(first, second, msg=msg)
  File "D:\python36\lib\unittest\case.py", line 1193, in assertMultiLineEqual
    self.fail(self._formatMessage(msg, standardMsg))
  File "D:\python36\lib\unittest\case.py", line 665, in fail
    raise self.failureException(msg)
AssertionError: 'OK' != 'JSON parse error: Cannot deserialize valu[363 chars]e"])'
- OK
+ JSON parse error: Cannot deserialize value of type `java.lang.Double` from String "年利率": not a valid Double value; nested exception is com.fasterxml.jackson.databind.exc.InvalidFormatException: Cannot deserialize value of type `java.lang.Double` from String "年利率": not a valid Double value
 at [Source: (PushbackInputStream); line: 1, column: 109] (through reference chain: com.lemon.pojo.Loan["loan_rate"])

2020-03-01 20:20:43,222 - [testcase_add.py-->line:64] - ERROR: 添加不成功_借款期限str用例测试不通过
2020-03-01 20:20:43,222 - [testcase_add.py-->line:65] - ERROR: 2 != 0
Traceback (most recent call last):
  File "D:\untitled\withdraw_interface\testcase\testcase_add.py", line 58, in testcase_add
    self.assertEqual(expected['code'],res_info['code'])
  File "D:\python36\lib\unittest\case.py", line 820, in assertEqual
    assertion_func(first, second, msg=msg)
  File "D:\python36\lib\unittest\case.py", line 813, in _baseAssertEqual
    raise self.failureException(msg)
AssertionError: 2 != 0
2020-03-01 20:20:43,345 - [testcase_add.py-->line:61] - INFO: 添加不成功_借款期限类型非1或2用例测试通过
2020-03-01 20:20:43,467 - [testcase_add.py-->line:61] - INFO: 添加不成功_竞标天数非法用例测试通过
2020-03-01 20:20:49,616 - [testcase_audit.py-->line:87] - INFO: 登录用例测试通过
2020-03-01 20:20:49,831 - [testcase_audit.py-->line:87] - INFO: 审核通过用例测试通过
2020-03-01 20:20:50,025 - [testcase_audit.py-->line:87] - INFO: 审核不通过用例测试通过
2020-03-01 20:20:50,217 - [testcase_audit.py-->line:87] - INFO: 项目不待审核状态用例测试通过
2020-03-01 20:20:50,388 - [testcase_audit.py-->line:90] - ERROR: 参数approved_or_not非法用例测试不通过
2020-03-01 20:20:50,388 - [testcase_audit.py-->line:91] - ERROR: 1004 != 0
Traceback (most recent call last):
  File "D:\untitled\withdraw_interface\testcase\testcase_audit.py", line 84, in testcase_audit
    self.assertEqual(expected['code'],res_info['code'])
  File "D:\python36\lib\unittest\case.py", line 820, in assertEqual
    assertion_func(first, second, msg=msg)
  File "D:\python36\lib\unittest\case.py", line 813, in _baseAssertEqual
    raise self.failureException(msg)
AssertionError: 1004 != 0
2020-03-01 20:20:50,604 - [testcase_audit.py-->line:90] - ERROR: 项目为空用例测试不通过
2020-03-01 20:20:50,604 - [testcase_audit.py-->line:91] - ERROR: 1004 != 0
Traceback (most recent call last):
  File "D:\untitled\withdraw_interface\testcase\testcase_audit.py", line 84, in testcase_audit
    self.assertEqual(expected['code'],res_info['code'])
  File "D:\python36\lib\unittest\case.py", line 820, in assertEqual
    assertion_func(first, second, msg=msg)
  File "D:\python36\lib\unittest\case.py", line 813, in _baseAssertEqual
    raise self.failureException(msg)
AssertionError: 1004 != 0
2020-03-01 20:20:50,808 - [testcase_audit.py-->line:90] - ERROR: 项目不存在用例测试不通过
2020-03-01 20:20:50,808 - [testcase_audit.py-->line:91] - ERROR: 1004 != 0
Traceback (most recent call last):
  File "D:\untitled\withdraw_interface\testcase\testcase_audit.py", line 84, in testcase_audit
    self.assertEqual(expected['code'],res_info['code'])
  File "D:\python36\lib\unittest\case.py", line 820, in assertEqual
    assertion_func(first, second, msg=msg)
  File "D:\python36\lib\unittest\case.py", line 813, in _baseAssertEqual
    raise self.failureException(msg)
AssertionError: 1004 != 0
2020-03-01 20:20:56,607 - [testcase_invest.py-->line:95] - INFO: 登录用例测试通过
2020-03-01 20:20:56,808 - [testcase_invest.py-->line:98] - ERROR: 投资不通过_投资项目非竞标状态用例测试不通过
2020-03-01 20:20:56,808 - [testcase_invest.py-->line:99] - ERROR: 1004 != 0
Traceback (most recent call last):
  File "D:\untitled\withdraw_interface\testcase\testcase_invest.py", line 92, in test_invest
    self.assertEqual(expected['code'],res_info['code'])
  File "D:\python36\lib\unittest\case.py", line 820, in assertEqual
    assertion_func(first, second, msg=msg)
  File "D:\python36\lib\unittest\case.py", line 813, in _baseAssertEqual
    raise self.failureException(msg)
AssertionError: 1004 != 0
2020-03-01 20:20:57,000 - [testcase_invest.py-->line:95] - INFO: 投资通过用例测试通过
2020-03-01 20:20:57,173 - [testcase_invest.py-->line:95] - INFO: 投资不通过_投资费非100整数用例测试通过
2020-03-01 20:20:57,378 - [testcase_invest.py-->line:95] - INFO: 投资不通过_投资费大于项目费用用例测试通过
2020-03-01 20:20:57,549 - [testcase_invest.py-->line:98] - ERROR: 投资不通过用例测试不通过
2020-03-01 20:20:57,549 - [testcase_invest.py-->line:99] - ERROR: 1004 != 0
Traceback (most recent call last):
  File "D:\untitled\withdraw_interface\testcase\testcase_invest.py", line 92, in test_invest
    self.assertEqual(expected['code'],res_info['code'])
  File "D:\python36\lib\unittest\case.py", line 820, in assertEqual
    assertion_func(first, second, msg=msg)
  File "D:\python36\lib\unittest\case.py", line 813, in _baseAssertEqual
    raise self.failureException(msg)
AssertionError: 1004 != 0
2020-03-01 20:20:57,759 - [testcase_invest.py-->line:98] - ERROR: 投资不通过用例测试不通过
2020-03-01 20:20:57,760 - [testcase_invest.py-->line:99] - ERROR: 1004 != 0
Traceback (most recent call last):
  File "D:\untitled\withdraw_interface\testcase\testcase_invest.py", line 92, in test_invest
    self.assertEqual(expected['code'],res_info['code'])
  File "D:\python36\lib\unittest\case.py", line 820, in assertEqual
    assertion_func(first, second, msg=msg)
  File "D:\python36\lib\unittest\case.py", line 813, in _baseAssertEqual
    raise self.failureException(msg)
AssertionError: 1004 != 0
2020-03-01 20:20:58,968 - [testcase_withdraw.py-->line:61] - INFO: 登录用例测试通过
2020-03-01 20:20:59,271 - [testcase_withdraw.py-->line:64] - ERROR: 提现成功用例测试不通过
2020-03-01 20:20:59,272 - [testcase_withdraw.py-->line:65] - ERROR: Decimal('10000') != Decimal('0.00')
Traceback (most recent call last):
  File "D:\untitled\withdraw_interface\testcase\testcase_withdraw.py", line 57, in testcase_withdraw
    self.assertEqual(Decimal(str(data['amount'])),(leave_amount_start-leave_amount_end))
  File "D:\python36\lib\unittest\case.py", line 820, in assertEqual
    assertion_func(first, second, msg=msg)
  File "D:\python36\lib\unittest\case.py", line 813, in _baseAssertEqual
    raise self.failureException(msg)
AssertionError: Decimal('10000') != Decimal('0.00')
2020-03-01 20:20:59,444 - [testcase_withdraw.py-->line:61] - INFO: 提现不成功-MemberId为空用例测试通过
2020-03-01 20:20:59,570 - [testcase_withdraw.py-->line:61] - INFO: 提现不成功-Amount为空用例测试通过
2020-03-01 20:20:59,696 - [testcase_withdraw.py-->line:61] - INFO: 提现不成功-Amount为负值用例测试通过
2020-03-01 20:20:59,822 - [testcase_withdraw.py-->line:61] - INFO: 提现不成功-Amount大于500000用例测试通过
2020-03-01 20:21:00,000 - [testcase_withdraw.py-->line:61] - INFO: 提现不成功-Amount的小数位数多于2位用例测试通过
2020-03-01 20:21:00,315 - [testcase_withdraw.py-->line:64] - ERROR: 提现成功-Amount的小数位数1位用例测试不通过
2020-03-01 20:21:00,316 - [testcase_withdraw.py-->line:65] - ERROR: Decimal('400000.1') != Decimal('0.00')
Traceback (most recent call last):
  File "D:\untitled\withdraw_interface\testcase\testcase_withdraw.py", line 57, in testcase_withdraw
    self.assertEqual(Decimal(str(data['amount'])),(leave_amount_start-leave_amount_end))
  File "D:\python36\lib\unittest\case.py", line 820, in assertEqual
    assertion_func(first, second, msg=msg)
  File "D:\python36\lib\unittest\case.py", line 813, in _baseAssertEqual
    raise self.failureException(msg)
AssertionError: Decimal('400000.1') != Decimal('0.00')
2020-03-01 20:21:00,623 - [testcase_withdraw.py-->line:64] - ERROR: 提现成功-Amount的小数位数2位用例测试不通过
2020-03-01 20:21:00,623 - [testcase_withdraw.py-->line:65] - ERROR: Decimal('400000.09') != Decimal('0.00')
Traceback (most recent call last):
  File "D:\untitled\withdraw_interface\testcase\testcase_withdraw.py", line 57, in testcase_withdraw
    self.assertEqual(Decimal(str(data['amount'])),(leave_amount_start-leave_amount_end))
  File "D:\python36\lib\unittest\case.py", line 820, in assertEqual
    assertion_func(first, second, msg=msg)
  File "D:\python36\lib\unittest\case.py", line 813, in _baseAssertEqual
    raise self.failureException(msg)
AssertionError: Decimal('400000.09') != Decimal('0.00')
2020-03-01 20:45:54,767 - [testcase_add.py-->line:61] - INFO: 登录用例测试通过
2020-03-01 20:45:55,313 - [testcase_add.py-->line:61] - INFO: 添加成功用例测试通过
2020-03-01 20:45:55,443 - [testcase_add.py-->line:61] - INFO: 添加成功_借款期限类型2用例测试通过
2020-03-01 20:45:55,592 - [testcase_add.py-->line:64] - ERROR: 添加不成功_标题为int用例测试不通过
2020-03-01 20:45:55,592 - [testcase_add.py-->line:65] - ERROR: 2 != 0
Traceback (most recent call last):
  File "D:\untitled\withdraw_interface\testcase\testcase_add.py", line 58, in testcase_add
    self.assertEqual(expected['code'],res_info['code'])
  File "D:\python36\lib\unittest\case.py", line 820, in assertEqual
    assertion_func(first, second, msg=msg)
  File "D:\python36\lib\unittest\case.py", line 813, in _baseAssertEqual
    raise self.failureException(msg)
AssertionError: 2 != 0
2020-03-01 20:45:55,844 - [testcase_add.py-->line:64] - ERROR: 添加不成功_借款金额str用例测试不通过
2020-03-01 20:45:55,844 - [testcase_add.py-->line:65] - ERROR: 'OK' != 'JSON parse error: Cannot deserialize valu[365 chars]t"])'
- OK
+ JSON parse error: Cannot deserialize value of type `java.lang.Double` from String "strstr": not a valid Double value; nested exception is com.fasterxml.jackson.databind.exc.InvalidFormatException: Cannot deserialize value of type `java.lang.Double` from String "strstr": not a valid Double value
 at [Source: (PushbackInputStream); line: 1, column: 52] (through reference chain: com.lemon.pojo.Loan["amount"])
Traceback (most recent call last):
  File "D:\untitled\withdraw_interface\testcase\testcase_add.py", line 59, in testcase_add
    self.assertEqual(expected['msg'],res_info['msg'])
  File "D:\python36\lib\unittest\case.py", line 820, in assertEqual
    assertion_func(first, second, msg=msg)
  File "D:\python36\lib\unittest\case.py", line 1193, in assertMultiLineEqual
    self.fail(self._formatMessage(msg, standardMsg))
  File "D:\python36\lib\unittest\case.py", line 665, in fail
    raise self.failureException(msg)
AssertionError: 'OK' != 'JSON parse error: Cannot deserialize valu[365 chars]t"])'
- OK
+ JSON parse error: Cannot deserialize value of type `java.lang.Double` from String "strstr": not a valid Double value; nested exception is com.fasterxml.jackson.databind.exc.InvalidFormatException: Cannot deserialize value of type `java.lang.Double` from String "strstr": not a valid Double value
 at [Source: (PushbackInputStream); line: 1, column: 52] (through reference chain: com.lemon.pojo.Loan["amount"])

2020-03-01 20:45:55,971 - [testcase_add.py-->line:64] - ERROR: 添加不成功_年利率str用例测试不通过
2020-03-01 20:45:55,971 - [testcase_add.py-->line:65] - ERROR: 'OK' != 'JSON parse error: Cannot deserialize valu[362 chars]e"])'
- OK
+ JSON parse error: Cannot deserialize value of type `java.lang.Double` from String "年利率": not a valid Double value; nested exception is com.fasterxml.jackson.databind.exc.InvalidFormatException: Cannot deserialize value of type `java.lang.Double` from String "年利率": not a valid Double value
 at [Source: (PushbackInputStream); line: 1, column: 73] (through reference chain: com.lemon.pojo.Loan["loan_rate"])
Traceback (most recent call last):
  File "D:\untitled\withdraw_interface\testcase\testcase_add.py", line 59, in testcase_add
    self.assertEqual(expected['msg'],res_info['msg'])
  File "D:\python36\lib\unittest\case.py", line 820, in assertEqual
    assertion_func(first, second, msg=msg)
  File "D:\python36\lib\unittest\case.py", line 1193, in assertMultiLineEqual
    self.fail(self._formatMessage(msg, standardMsg))
  File "D:\python36\lib\unittest\case.py", line 665, in fail
    raise self.failureException(msg)
AssertionError: 'OK' != 'JSON parse error: Cannot deserialize valu[362 chars]e"])'
- OK
+ JSON parse error: Cannot deserialize value of type `java.lang.Double` from String "年利率": not a valid Double value; nested exception is com.fasterxml.jackson.databind.exc.InvalidFormatException: Cannot deserialize value of type `java.lang.Double` from String "年利率": not a valid Double value
 at [Source: (PushbackInputStream); line: 1, column: 73] (through reference chain: com.lemon.pojo.Loan["loan_rate"])

2020-03-01 20:45:56,115 - [testcase_add.py-->line:64] - ERROR: 添加不成功_借款期限str用例测试不通过
2020-03-01 20:45:56,115 - [testcase_add.py-->line:65] - ERROR: 2 != 0
Traceback (most recent call last):
  File "D:\untitled\withdraw_interface\testcase\testcase_add.py", line 58, in testcase_add
    self.assertEqual(expected['code'],res_info['code'])
  File "D:\python36\lib\unittest\case.py", line 820, in assertEqual
    assertion_func(first, second, msg=msg)
  File "D:\python36\lib\unittest\case.py", line 813, in _baseAssertEqual
    raise self.failureException(msg)
AssertionError: 2 != 0
2020-03-01 20:45:56,266 - [testcase_add.py-->line:61] - INFO: 添加不成功_借款期限类型非1或2用例测试通过
2020-03-01 20:45:56,417 - [testcase_add.py-->line:61] - INFO: 添加不成功_竞标天数非法用例测试通过
2020-03-01 20:46:00,624 - [testcase_audit.py-->line:87] - INFO: 登录用例测试通过
2020-03-01 20:46:00,812 - [testcase_audit.py-->line:87] - INFO: 审核通过用例测试通过
2020-03-01 20:46:01,003 - [testcase_audit.py-->line:87] - INFO: 审核不通过用例测试通过
2020-03-01 20:46:01,195 - [testcase_audit.py-->line:87] - INFO: 项目不待审核状态用例测试通过
2020-03-01 20:46:01,411 - [testcase_audit.py-->line:90] - ERROR: 参数approved_or_not非法用例测试不通过
2020-03-01 20:46:01,412 - [testcase_audit.py-->line:91] - ERROR: 1004 != 0
Traceback (most recent call last):
  File "D:\untitled\withdraw_interface\testcase\testcase_audit.py", line 84, in testcase_audit
    self.assertEqual(expected['code'],res_info['code'])
  File "D:\python36\lib\unittest\case.py", line 820, in assertEqual
    assertion_func(first, second, msg=msg)
  File "D:\python36\lib\unittest\case.py", line 813, in _baseAssertEqual
    raise self.failureException(msg)
AssertionError: 1004 != 0
2020-03-01 20:46:01,611 - [testcase_audit.py-->line:90] - ERROR: 项目为空用例测试不通过
2020-03-01 20:46:01,611 - [testcase_audit.py-->line:91] - ERROR: 1004 != 0
Traceback (most recent call last):
  File "D:\untitled\withdraw_interface\testcase\testcase_audit.py", line 84, in testcase_audit
    self.assertEqual(expected['code'],res_info['code'])
  File "D:\python36\lib\unittest\case.py", line 820, in assertEqual
    assertion_func(first, second, msg=msg)
  File "D:\python36\lib\unittest\case.py", line 813, in _baseAssertEqual
    raise self.failureException(msg)
AssertionError: 1004 != 0
2020-03-01 20:46:01,783 - [testcase_audit.py-->line:90] - ERROR: 项目不存在用例测试不通过
2020-03-01 20:46:01,783 - [testcase_audit.py-->line:91] - ERROR: 1004 != 0
Traceback (most recent call last):
  File "D:\untitled\withdraw_interface\testcase\testcase_audit.py", line 84, in testcase_audit
    self.assertEqual(expected['code'],res_info['code'])
  File "D:\python36\lib\unittest\case.py", line 820, in assertEqual
    assertion_func(first, second, msg=msg)
  File "D:\python36\lib\unittest\case.py", line 813, in _baseAssertEqual
    raise self.failureException(msg)
AssertionError: 1004 != 0
2020-03-01 20:46:07,118 - [testcase_invest.py-->line:96] - INFO: 登录用例测试通过
2020-03-01 20:46:07,201 - [testcase_invest.py-->line:99] - ERROR: 投资不通过_投资项目非竞标状态用例测试不通过
2020-03-01 20:46:07,201 - [testcase_invest.py-->line:100] - ERROR: 1004 != 0
Traceback (most recent call last):
  File "D:\untitled\withdraw_interface\testcase\testcase_invest.py", line 93, in test_invest
    self.assertEqual(expected['code'],res_info['code'])
  File "D:\python36\lib\unittest\case.py", line 820, in assertEqual
    assertion_func(first, second, msg=msg)
  File "D:\python36\lib\unittest\case.py", line 813, in _baseAssertEqual
    raise self.failureException(msg)
AssertionError: 1004 != 0
2020-03-01 20:46:07,286 - [testcase_invest.py-->line:96] - INFO: 投资通过用例测试通过
2020-03-01 20:46:07,368 - [testcase_invest.py-->line:96] - INFO: 投资不通过_投资费非100整数用例测试通过
2020-03-01 20:46:07,451 - [testcase_invest.py-->line:96] - INFO: 投资不通过_投资费大于项目费用用例测试通过
2020-03-01 20:46:07,535 - [testcase_invest.py-->line:99] - ERROR: 投资不通过用例测试不通过
2020-03-01 20:46:07,535 - [testcase_invest.py-->line:100] - ERROR: 1004 != 0
Traceback (most recent call last):
  File "D:\untitled\withdraw_interface\testcase\testcase_invest.py", line 93, in test_invest
    self.assertEqual(expected['code'],res_info['code'])
  File "D:\python36\lib\unittest\case.py", line 820, in assertEqual
    assertion_func(first, second, msg=msg)
  File "D:\python36\lib\unittest\case.py", line 813, in _baseAssertEqual
    raise self.failureException(msg)
AssertionError: 1004 != 0
2020-03-01 20:46:07,621 - [testcase_invest.py-->line:99] - ERROR: 投资不通过用例测试不通过
2020-03-01 20:46:07,621 - [testcase_invest.py-->line:100] - ERROR: 1004 != 0
Traceback (most recent call last):
  File "D:\untitled\withdraw_interface\testcase\testcase_invest.py", line 93, in test_invest
    self.assertEqual(expected['code'],res_info['code'])
  File "D:\python36\lib\unittest\case.py", line 820, in assertEqual
    assertion_func(first, second, msg=msg)
  File "D:\python36\lib\unittest\case.py", line 813, in _baseAssertEqual
    raise self.failureException(msg)
AssertionError: 1004 != 0
2020-03-01 20:46:11,607 - [testcase_withdraw.py-->line:61] - INFO: 登录用例测试通过
2020-03-01 20:46:11,942 - [testcase_withdraw.py-->line:64] - ERROR: 提现成功用例测试不通过
2020-03-01 20:46:11,942 - [testcase_withdraw.py-->line:65] - ERROR: Decimal('10000') != Decimal('0.00')
Traceback (most recent call last):
  File "D:\untitled\withdraw_interface\testcase\testcase_withdraw.py", line 57, in testcase_withdraw
    self.assertEqual(Decimal(str(data['amount'])),(leave_amount_start-leave_amount_end))
  File "D:\python36\lib\unittest\case.py", line 820, in assertEqual
    assertion_func(first, second, msg=msg)
  File "D:\python36\lib\unittest\case.py", line 813, in _baseAssertEqual
    raise self.failureException(msg)
AssertionError: Decimal('10000') != Decimal('0.00')
2020-03-01 20:46:12,108 - [testcase_withdraw.py-->line:61] - INFO: 提现不成功-MemberId为空用例测试通过
2020-03-01 20:46:12,243 - [testcase_withdraw.py-->line:61] - INFO: 提现不成功-Amount为空用例测试通过
2020-03-01 20:46:12,390 - [testcase_withdraw.py-->line:61] - INFO: 提现不成功-Amount为负值用例测试通过
2020-03-01 20:46:12,537 - [testcase_withdraw.py-->line:61] - INFO: 提现不成功-Amount大于500000用例测试通过
2020-03-01 20:46:12,720 - [testcase_withdraw.py-->line:61] - INFO: 提现不成功-Amount的小数位数多于2位用例测试通过
2020-03-01 20:46:13,029 - [testcase_withdraw.py-->line:64] - ERROR: 提现成功-Amount的小数位数1位用例测试不通过
2020-03-01 20:46:13,029 - [testcase_withdraw.py-->line:65] - ERROR: Decimal('400000.1') != Decimal('0.00')
Traceback (most recent call last):
  File "D:\untitled\withdraw_interface\testcase\testcase_withdraw.py", line 57, in testcase_withdraw
    self.assertEqual(Decimal(str(data['amount'])),(leave_amount_start-leave_amount_end))
  File "D:\python36\lib\unittest\case.py", line 820, in assertEqual
    assertion_func(first, second, msg=msg)
  File "D:\python36\lib\unittest\case.py", line 813, in _baseAssertEqual
    raise self.failureException(msg)
AssertionError: Decimal('400000.1') != Decimal('0.00')
2020-03-01 20:46:13,319 - [testcase_withdraw.py-->line:64] - ERROR: 提现成功-Amount的小数位数2位用例测试不通过
2020-03-01 20:46:13,320 - [testcase_withdraw.py-->line:65] - ERROR: Decimal('400000.09') != Decimal('0.00')
Traceback (most recent call last):
  File "D:\untitled\withdraw_interface\testcase\testcase_withdraw.py", line 57, in testcase_withdraw
    self.assertEqual(Decimal(str(data['amount'])),(leave_amount_start-leave_amount_end))
  File "D:\python36\lib\unittest\case.py", line 820, in assertEqual
    assertion_func(first, second, msg=msg)
  File "D:\python36\lib\unittest\case.py", line 813, in _baseAssertEqual
    raise self.failureException(msg)
AssertionError: Decimal('400000.09') != Decimal('0.00')
2020-03-01 20:53:52,616 - [testcase_add.py-->line:61] - INFO: 登录用例测试通过
2020-03-01 20:53:52,910 - [testcase_add.py-->line:61] - INFO: 添加成功用例测试通过
2020-03-01 20:53:53,037 - [testcase_add.py-->line:61] - INFO: 添加成功_借款期限类型2用例测试通过
2020-03-01 20:53:53,165 - [testcase_add.py-->line:64] - ERROR: 添加不成功_标题为int用例测试不通过
2020-03-01 20:53:53,165 - [testcase_add.py-->line:65] - ERROR: 2 != 0
Traceback (most recent call last):
  File "D:\untitled\withdraw_interface\testcase\testcase_add.py", line 58, in testcase_add
    self.assertEqual(expected['code'],res_info['code'])
  File "D:\python36\lib\unittest\case.py", line 820, in assertEqual
    assertion_func(first, second, msg=msg)
  File "D:\python36\lib\unittest\case.py", line 813, in _baseAssertEqual
    raise self.failureException(msg)
AssertionError: 2 != 0
2020-03-01 20:53:53,310 - [testcase_add.py-->line:64] - ERROR: 添加不成功_借款金额str用例测试不通过
2020-03-01 20:53:53,310 - [testcase_add.py-->line:65] - ERROR: 'OK' != 'JSON parse error: Cannot deserialize valu[365 chars]t"])'
- OK
+ JSON parse error: Cannot deserialize value of type `java.lang.Double` from String "strstr": not a valid Double value; nested exception is com.fasterxml.jackson.databind.exc.InvalidFormatException: Cannot deserialize value of type `java.lang.Double` from String "strstr": not a valid Double value
 at [Source: (PushbackInputStream); line: 1, column: 71] (through reference chain: com.lemon.pojo.Loan["amount"])
Traceback (most recent call last):
  File "D:\untitled\withdraw_interface\testcase\testcase_add.py", line 59, in testcase_add
    self.assertEqual(expected['msg'],res_info['msg'])
  File "D:\python36\lib\unittest\case.py", line 820, in assertEqual
    assertion_func(first, second, msg=msg)
  File "D:\python36\lib\unittest\case.py", line 1193, in assertMultiLineEqual
    self.fail(self._formatMessage(msg, standardMsg))
  File "D:\python36\lib\unittest\case.py", line 665, in fail
    raise self.failureException(msg)
AssertionError: 'OK' != 'JSON parse error: Cannot deserialize valu[365 chars]t"])'
- OK
+ JSON parse error: Cannot deserialize value of type `java.lang.Double` from String "strstr": not a valid Double value; nested exception is com.fasterxml.jackson.databind.exc.InvalidFormatException: Cannot deserialize value of type `java.lang.Double` from String "strstr": not a valid Double value
 at [Source: (PushbackInputStream); line: 1, column: 71] (through reference chain: com.lemon.pojo.Loan["amount"])

2020-03-01 20:53:53,436 - [testcase_add.py-->line:64] - ERROR: 添加不成功_年利率str用例测试不通过
2020-03-01 20:53:53,437 - [testcase_add.py-->line:65] - ERROR: 'OK' != 'JSON parse error: Cannot deserialize valu[363 chars]e"])'
- OK
+ JSON parse error: Cannot deserialize value of type `java.lang.Double` from String "年利率": not a valid Double value; nested exception is com.fasterxml.jackson.databind.exc.InvalidFormatException: Cannot deserialize value of type `java.lang.Double` from String "年利率": not a valid Double value
 at [Source: (PushbackInputStream); line: 1, column: 109] (through reference chain: com.lemon.pojo.Loan["loan_rate"])
Traceback (most recent call last):
  File "D:\untitled\withdraw_interface\testcase\testcase_add.py", line 59, in testcase_add
    self.assertEqual(expected['msg'],res_info['msg'])
  File "D:\python36\lib\unittest\case.py", line 820, in assertEqual
    assertion_func(first, second, msg=msg)
  File "D:\python36\lib\unittest\case.py", line 1193, in assertMultiLineEqual
    self.fail(self._formatMessage(msg, standardMsg))
  File "D:\python36\lib\unittest\case.py", line 665, in fail
    raise self.failureException(msg)
AssertionError: 'OK' != 'JSON parse error: Cannot deserialize valu[363 chars]e"])'
- OK
+ JSON parse error: Cannot deserialize value of type `java.lang.Double` from String "年利率": not a valid Double value; nested exception is com.fasterxml.jackson.databind.exc.InvalidFormatException: Cannot deserialize value of type `java.lang.Double` from String "年利率": not a valid Double value
 at [Source: (PushbackInputStream); line: 1, column: 109] (through reference chain: com.lemon.pojo.Loan["loan_rate"])

2020-03-01 20:53:53,591 - [testcase_add.py-->line:64] - ERROR: 添加不成功_借款期限str用例测试不通过
2020-03-01 20:53:53,591 - [testcase_add.py-->line:65] - ERROR: 2 != 0
Traceback (most recent call last):
  File "D:\untitled\withdraw_interface\testcase\testcase_add.py", line 58, in testcase_add
    self.assertEqual(expected['code'],res_info['code'])
  File "D:\python36\lib\unittest\case.py", line 820, in assertEqual
    assertion_func(first, second, msg=msg)
  File "D:\python36\lib\unittest\case.py", line 813, in _baseAssertEqual
    raise self.failureException(msg)
AssertionError: 2 != 0
2020-03-01 20:53:54,022 - [testcase_add.py-->line:61] - INFO: 添加不成功_借款期限类型非1或2用例测试通过
2020-03-01 20:53:54,145 - [testcase_add.py-->line:61] - INFO: 添加不成功_竞标天数非法用例测试通过
2020-03-01 20:53:58,253 - [testcase_audit.py-->line:87] - INFO: 登录用例测试通过
2020-03-01 20:53:58,438 - [testcase_audit.py-->line:87] - INFO: 审核通过用例测试通过
2020-03-01 20:53:58,619 - [testcase_audit.py-->line:87] - INFO: 审核不通过用例测试通过
2020-03-01 20:53:58,800 - [testcase_audit.py-->line:87] - INFO: 项目不待审核状态用例测试通过
2020-03-01 20:53:58,988 - [testcase_audit.py-->line:90] - ERROR: 参数approved_or_not非法用例测试不通过
2020-03-01 20:53:58,988 - [testcase_audit.py-->line:91] - ERROR: 1004 != 0
Traceback (most recent call last):
  File "D:\untitled\withdraw_interface\testcase\testcase_audit.py", line 84, in testcase_audit
    self.assertEqual(expected['code'],res_info['code'])
  File "D:\python36\lib\unittest\case.py", line 820, in assertEqual
    assertion_func(first, second, msg=msg)
  File "D:\python36\lib\unittest\case.py", line 813, in _baseAssertEqual
    raise self.failureException(msg)
AssertionError: 1004 != 0
2020-03-01 20:53:59,170 - [testcase_audit.py-->line:90] - ERROR: 项目为空用例测试不通过
2020-03-01 20:53:59,170 - [testcase_audit.py-->line:91] - ERROR: 1004 != 0
Traceback (most recent call last):
  File "D:\untitled\withdraw_interface\testcase\testcase_audit.py", line 84, in testcase_audit
    self.assertEqual(expected['code'],res_info['code'])
  File "D:\python36\lib\unittest\case.py", line 820, in assertEqual
    assertion_func(first, second, msg=msg)
  File "D:\python36\lib\unittest\case.py", line 813, in _baseAssertEqual
    raise self.failureException(msg)
AssertionError: 1004 != 0
2020-03-01 20:53:59,354 - [testcase_audit.py-->line:90] - ERROR: 项目不存在用例测试不通过
2020-03-01 20:53:59,354 - [testcase_audit.py-->line:91] - ERROR: 1004 != 0
Traceback (most recent call last):
  File "D:\untitled\withdraw_interface\testcase\testcase_audit.py", line 84, in testcase_audit
    self.assertEqual(expected['code'],res_info['code'])
  File "D:\python36\lib\unittest\case.py", line 820, in assertEqual
    assertion_func(first, second, msg=msg)
  File "D:\python36\lib\unittest\case.py", line 813, in _baseAssertEqual
    raise self.failureException(msg)
AssertionError: 1004 != 0
2020-03-01 20:54:03,611 - [testcase_invest.py-->line:96] - INFO: 登录用例测试通过
2020-03-01 20:54:03,694 - [testcase_invest.py-->line:99] - ERROR: 投资不通过_投资项目非竞标状态用例测试不通过
2020-03-01 20:54:03,694 - [testcase_invest.py-->line:100] - ERROR: 1004 != 0
Traceback (most recent call last):
  File "D:\untitled\withdraw_interface\testcase\testcase_invest.py", line 93, in test_invest
    self.assertEqual(expected['code'],res_info['code'])
  File "D:\python36\lib\unittest\case.py", line 820, in assertEqual
    assertion_func(first, second, msg=msg)
  File "D:\python36\lib\unittest\case.py", line 813, in _baseAssertEqual
    raise self.failureException(msg)
AssertionError: 1004 != 0
2020-03-01 20:54:03,777 - [testcase_invest.py-->line:96] - INFO: 投资通过用例测试通过
2020-03-01 20:54:03,859 - [testcase_invest.py-->line:96] - INFO: 投资不通过_投资费非100整数用例测试通过
2020-03-01 20:54:03,941 - [testcase_invest.py-->line:96] - INFO: 投资不通过_投资费大于项目费用用例测试通过
2020-03-01 20:54:04,024 - [testcase_invest.py-->line:99] - ERROR: 投资不通过用例测试不通过
2020-03-01 20:54:04,024 - [testcase_invest.py-->line:100] - ERROR: 1004 != 0
Traceback (most recent call last):
  File "D:\untitled\withdraw_interface\testcase\testcase_invest.py", line 93, in test_invest
    self.assertEqual(expected['code'],res_info['code'])
  File "D:\python36\lib\unittest\case.py", line 820, in assertEqual
    assertion_func(first, second, msg=msg)
  File "D:\python36\lib\unittest\case.py", line 813, in _baseAssertEqual
    raise self.failureException(msg)
AssertionError: 1004 != 0
2020-03-01 20:54:04,109 - [testcase_invest.py-->line:99] - ERROR: 投资不通过用例测试不通过
2020-03-01 20:54:04,109 - [testcase_invest.py-->line:100] - ERROR: 1004 != 0
Traceback (most recent call last):
  File "D:\untitled\withdraw_interface\testcase\testcase_invest.py", line 93, in test_invest
    self.assertEqual(expected['code'],res_info['code'])
  File "D:\python36\lib\unittest\case.py", line 820, in assertEqual
    assertion_func(first, second, msg=msg)
  File "D:\python36\lib\unittest\case.py", line 813, in _baseAssertEqual
    raise self.failureException(msg)
AssertionError: 1004 != 0
2020-03-01 20:54:07,109 - [testcase_withdraw.py-->line:61] - INFO: 登录用例测试通过
2020-03-01 20:54:07,594 - [testcase_withdraw.py-->line:64] - ERROR: 提现成功用例测试不通过
2020-03-01 20:54:07,594 - [testcase_withdraw.py-->line:65] - ERROR: Decimal('10000') != Decimal('0.00')
Traceback (most recent call last):
  File "D:\untitled\withdraw_interface\testcase\testcase_withdraw.py", line 57, in testcase_withdraw
    self.assertEqual(Decimal(str(data['amount'])),(leave_amount_start-leave_amount_end))
  File "D:\python36\lib\unittest\case.py", line 820, in assertEqual
    assertion_func(first, second, msg=msg)
  File "D:\python36\lib\unittest\case.py", line 813, in _baseAssertEqual
    raise self.failureException(msg)
AssertionError: Decimal('10000') != Decimal('0.00')
2020-03-01 20:54:07,718 - [testcase_withdraw.py-->line:61] - INFO: 提现不成功-MemberId为空用例测试通过
2020-03-01 20:54:07,857 - [testcase_withdraw.py-->line:61] - INFO: 提现不成功-Amount为空用例测试通过
2020-03-01 20:54:08,260 - [testcase_withdraw.py-->line:61] - INFO: 提现不成功-Amount为负值用例测试通过
2020-03-01 20:54:08,398 - [testcase_withdraw.py-->line:61] - INFO: 提现不成功-Amount大于500000用例测试通过
2020-03-01 20:54:08,542 - [testcase_withdraw.py-->line:61] - INFO: 提现不成功-Amount的小数位数多于2位用例测试通过
2020-03-01 20:54:08,816 - [testcase_withdraw.py-->line:64] - ERROR: 提现成功-Amount的小数位数1位用例测试不通过
2020-03-01 20:54:08,816 - [testcase_withdraw.py-->line:65] - ERROR: Decimal('400000.1') != Decimal('0.00')
Traceback (most recent call last):
  File "D:\untitled\withdraw_interface\testcase\testcase_withdraw.py", line 57, in testcase_withdraw
    self.assertEqual(Decimal(str(data['amount'])),(leave_amount_start-leave_amount_end))
  File "D:\python36\lib\unittest\case.py", line 820, in assertEqual
    assertion_func(first, second, msg=msg)
  File "D:\python36\lib\unittest\case.py", line 813, in _baseAssertEqual
    raise self.failureException(msg)
AssertionError: Decimal('400000.1') != Decimal('0.00')
2020-03-01 20:54:09,109 - [testcase_withdraw.py-->line:64] - ERROR: 提现成功-Amount的小数位数2位用例测试不通过
2020-03-01 20:54:09,109 - [testcase_withdraw.py-->line:65] - ERROR: Decimal('400000.09') != Decimal('0.00')
Traceback (most recent call last):
  File "D:\untitled\withdraw_interface\testcase\testcase_withdraw.py", line 57, in testcase_withdraw
    self.assertEqual(Decimal(str(data['amount'])),(leave_amount_start-leave_amount_end))
  File "D:\python36\lib\unittest\case.py", line 820, in assertEqual
    assertion_func(first, second, msg=msg)
  File "D:\python36\lib\unittest\case.py", line 813, in _baseAssertEqual
    raise self.failureException(msg)
AssertionError: Decimal('400000.09') != Decimal('0.00')
2020-03-01 21:17:22,959 - [testcase_add.py-->line:61] - INFO: 登录用例测试通过
2020-03-01 21:17:23,276 - [testcase_add.py-->line:61] - INFO: 添加成功用例测试通过
2020-03-01 21:17:23,409 - [testcase_add.py-->line:61] - INFO: 添加成功_借款期限类型2用例测试通过
2020-03-01 21:17:23,564 - [testcase_add.py-->line:64] - ERROR: 添加不成功_标题为int用例测试不通过
2020-03-01 21:17:23,564 - [testcase_add.py-->line:65] - ERROR: 2 != 0
Traceback (most recent call last):
  File "D:\untitled\withdraw_interface\testcase\testcase_add.py", line 58, in testcase_add
    self.assertEqual(expected['code'],res_info['code'])
  File "D:\python36\lib\unittest\case.py", line 820, in assertEqual
    assertion_func(first, second, msg=msg)
  File "D:\python36\lib\unittest\case.py", line 813, in _baseAssertEqual
    raise self.failureException(msg)
AssertionError: 2 != 0
2020-03-01 21:17:23,749 - [testcase_add.py-->line:64] - ERROR: 添加不成功_借款金额str用例测试不通过
2020-03-01 21:17:23,749 - [testcase_add.py-->line:65] - ERROR: 'OK' != 'JSON parse error: Cannot deserialize valu[365 chars]t"])'
- OK
+ JSON parse error: Cannot deserialize value of type `java.lang.Double` from String "strstr": not a valid Double value; nested exception is com.fasterxml.jackson.databind.exc.InvalidFormatException: Cannot deserialize value of type `java.lang.Double` from String "strstr": not a valid Double value
 at [Source: (PushbackInputStream); line: 1, column: 69] (through reference chain: com.lemon.pojo.Loan["amount"])
Traceback (most recent call last):
  File "D:\untitled\withdraw_interface\testcase\testcase_add.py", line 59, in testcase_add
    self.assertEqual(expected['msg'],res_info['msg'])
  File "D:\python36\lib\unittest\case.py", line 820, in assertEqual
    assertion_func(first, second, msg=msg)
  File "D:\python36\lib\unittest\case.py", line 1193, in assertMultiLineEqual
    self.fail(self._formatMessage(msg, standardMsg))
  File "D:\python36\lib\unittest\case.py", line 665, in fail
    raise self.failureException(msg)
AssertionError: 'OK' != 'JSON parse error: Cannot deserialize valu[365 chars]t"])'
- OK
+ JSON parse error: Cannot deserialize value of type `java.lang.Double` from String "strstr": not a valid Double value; nested exception is com.fasterxml.jackson.databind.exc.InvalidFormatException: Cannot deserialize value of type `java.lang.Double` from String "strstr": not a valid Double value
 at [Source: (PushbackInputStream); line: 1, column: 69] (through reference chain: com.lemon.pojo.Loan["amount"])

2020-03-01 21:17:23,876 - [testcase_add.py-->line:64] - ERROR: 添加不成功_年利率str用例测试不通过
2020-03-01 21:17:23,877 - [testcase_add.py-->line:65] - ERROR: 'OK' != 'JSON parse error: Cannot deserialize valu[363 chars]e"])'
- OK
+ JSON parse error: Cannot deserialize value of type `java.lang.Double` from String "年利率": not a valid Double value; nested exception is com.fasterxml.jackson.databind.exc.InvalidFormatException: Cannot deserialize value of type `java.lang.Double` from String "年利率": not a valid Double value
 at [Source: (PushbackInputStream); line: 1, column: 137] (through reference chain: com.lemon.pojo.Loan["loan_rate"])
Traceback (most recent call last):
  File "D:\untitled\withdraw_interface\testcase\testcase_add.py", line 59, in testcase_add
    self.assertEqual(expected['msg'],res_info['msg'])
  File "D:\python36\lib\unittest\case.py", line 820, in assertEqual
    assertion_func(first, second, msg=msg)
  File "D:\python36\lib\unittest\case.py", line 1193, in assertMultiLineEqual
    self.fail(self._formatMessage(msg, standardMsg))
  File "D:\python36\lib\unittest\case.py", line 665, in fail
    raise self.failureException(msg)
AssertionError: 'OK' != 'JSON parse error: Cannot deserialize valu[363 chars]e"])'
- OK
+ JSON parse error: Cannot deserialize value of type `java.lang.Double` from String "年利率": not a valid Double value; nested exception is com.fasterxml.jackson.databind.exc.InvalidFormatException: Cannot deserialize value of type `java.lang.Double` from String "年利率": not a valid Double value
 at [Source: (PushbackInputStream); line: 1, column: 137] (through reference chain: com.lemon.pojo.Loan["loan_rate"])

2020-03-01 21:17:24,040 - [testcase_add.py-->line:64] - ERROR: 添加不成功_借款期限str用例测试不通过
2020-03-01 21:17:24,040 - [testcase_add.py-->line:65] - ERROR: 2 != 0
Traceback (most recent call last):
  File "D:\untitled\withdraw_interface\testcase\testcase_add.py", line 58, in testcase_add
    self.assertEqual(expected['code'],res_info['code'])
  File "D:\python36\lib\unittest\case.py", line 820, in assertEqual
    assertion_func(first, second, msg=msg)
  File "D:\python36\lib\unittest\case.py", line 813, in _baseAssertEqual
    raise self.failureException(msg)
AssertionError: 2 != 0
2020-03-01 21:17:24,162 - [testcase_add.py-->line:61] - INFO: 添加不成功_借款期限类型非1或2用例测试通过
2020-03-01 21:17:24,284 - [testcase_add.py-->line:61] - INFO: 添加不成功_竞标天数非法用例测试通过
2020-03-01 21:17:28,823 - [testcase_audit.py-->line:87] - INFO: 登录用例测试通过
2020-03-01 21:17:29,021 - [testcase_audit.py-->line:87] - INFO: 审核通过用例测试通过
2020-03-01 21:17:29,210 - [testcase_audit.py-->line:87] - INFO: 审核不通过用例测试通过
2020-03-01 21:17:29,377 - [testcase_audit.py-->line:87] - INFO: 项目不待审核状态用例测试通过
2020-03-01 21:17:29,571 - [testcase_audit.py-->line:90] - ERROR: 参数approved_or_not非法用例测试不通过
2020-03-01 21:17:29,571 - [testcase_audit.py-->line:91] - ERROR: 1004 != 0
Traceback (most recent call last):
  File "D:\untitled\withdraw_interface\testcase\testcase_audit.py", line 84, in testcase_audit
    self.assertEqual(expected['code'],res_info['code'])
  File "D:\python36\lib\unittest\case.py", line 820, in assertEqual
    assertion_func(first, second, msg=msg)
  File "D:\python36\lib\unittest\case.py", line 813, in _baseAssertEqual
    raise self.failureException(msg)
AssertionError: 1004 != 0
2020-03-01 21:17:29,827 - [testcase_audit.py-->line:90] - ERROR: 项目为空用例测试不通过
2020-03-01 21:17:29,827 - [testcase_audit.py-->line:91] - ERROR: 1004 != 0
Traceback (most recent call last):
  File "D:\untitled\withdraw_interface\testcase\testcase_audit.py", line 84, in testcase_audit
    self.assertEqual(expected['code'],res_info['code'])
  File "D:\python36\lib\unittest\case.py", line 820, in assertEqual
    assertion_func(first, second, msg=msg)
  File "D:\python36\lib\unittest\case.py", line 813, in _baseAssertEqual
    raise self.failureException(msg)
AssertionError: 1004 != 0
2020-03-01 21:17:30,012 - [testcase_audit.py-->line:90] - ERROR: 项目不存在用例测试不通过
2020-03-01 21:17:30,012 - [testcase_audit.py-->line:91] - ERROR: 1004 != 0
Traceback (most recent call last):
  File "D:\untitled\withdraw_interface\testcase\testcase_audit.py", line 84, in testcase_audit
    self.assertEqual(expected['code'],res_info['code'])
  File "D:\python36\lib\unittest\case.py", line 820, in assertEqual
    assertion_func(first, second, msg=msg)
  File "D:\python36\lib\unittest\case.py", line 813, in _baseAssertEqual
    raise self.failureException(msg)
AssertionError: 1004 != 0
2020-03-01 21:17:36,090 - [testcase_invest.py-->line:98] - INFO: 登录用例测试通过
2020-03-01 21:17:36,173 - [testcase_invest.py-->line:101] - ERROR: 投资不通过_投资项目非竞标状态用例测试不通过
2020-03-01 21:17:36,173 - [testcase_invest.py-->line:102] - ERROR: 1004 != 0
Traceback (most recent call last):
  File "D:\untitled\withdraw_interface\testcase\testcase_invest.py", line 95, in test_invest
    self.assertEqual(expected['code'],res_info['code'])
  File "D:\python36\lib\unittest\case.py", line 820, in assertEqual
    assertion_func(first, second, msg=msg)
  File "D:\python36\lib\unittest\case.py", line 813, in _baseAssertEqual
    raise self.failureException(msg)
AssertionError: 1004 != 0
2020-03-01 21:17:36,256 - [testcase_invest.py-->line:98] - INFO: 投资通过用例测试通过
2020-03-01 21:17:36,337 - [testcase_invest.py-->line:98] - INFO: 投资不通过_投资费非100整数用例测试通过
2020-03-01 21:17:36,419 - [testcase_invest.py-->line:98] - INFO: 投资不通过_投资费大于项目费用用例测试通过
2020-03-01 21:17:36,501 - [testcase_invest.py-->line:101] - ERROR: 投资不通过用例测试不通过
2020-03-01 21:17:36,501 - [testcase_invest.py-->line:102] - ERROR: 1004 != 0
Traceback (most recent call last):
  File "D:\untitled\withdraw_interface\testcase\testcase_invest.py", line 95, in test_invest
    self.assertEqual(expected['code'],res_info['code'])
  File "D:\python36\lib\unittest\case.py", line 820, in assertEqual
    assertion_func(first, second, msg=msg)
  File "D:\python36\lib\unittest\case.py", line 813, in _baseAssertEqual
    raise self.failureException(msg)
AssertionError: 1004 != 0
2020-03-01 21:17:36,585 - [testcase_invest.py-->line:101] - ERROR: 投资不通过用例测试不通过
2020-03-01 21:17:36,585 - [testcase_invest.py-->line:102] - ERROR: 1004 != 0
Traceback (most recent call last):
  File "D:\untitled\withdraw_interface\testcase\testcase_invest.py", line 95, in test_invest
    self.assertEqual(expected['code'],res_info['code'])
  File "D:\python36\lib\unittest\case.py", line 820, in assertEqual
    assertion_func(first, second, msg=msg)
  File "D:\python36\lib\unittest\case.py", line 813, in _baseAssertEqual
    raise self.failureException(msg)
AssertionError: 1004 != 0
2020-03-01 21:17:37,771 - [testcase_withdraw.py-->line:61] - INFO: 登录用例测试通过
2020-03-01 21:17:38,129 - [testcase_withdraw.py-->line:64] - ERROR: 提现成功用例测试不通过
2020-03-01 21:17:38,130 - [testcase_withdraw.py-->line:65] - ERROR: Decimal('10000') != Decimal('0.00')
Traceback (most recent call last):
  File "D:\untitled\withdraw_interface\testcase\testcase_withdraw.py", line 57, in testcase_withdraw
    self.assertEqual(Decimal(str(data['amount'])),(leave_amount_start-leave_amount_end))
  File "D:\python36\lib\unittest\case.py", line 820, in assertEqual
    assertion_func(first, second, msg=msg)
  File "D:\python36\lib\unittest\case.py", line 813, in _baseAssertEqual
    raise self.failureException(msg)
AssertionError: Decimal('10000') != Decimal('0.00')
2020-03-01 21:17:38,288 - [testcase_withdraw.py-->line:61] - INFO: 提现不成功-MemberId为空用例测试通过
2020-03-01 21:17:38,427 - [testcase_withdraw.py-->line:61] - INFO: 提现不成功-Amount为空用例测试通过
2020-03-01 21:17:38,549 - [testcase_withdraw.py-->line:61] - INFO: 提现不成功-Amount为负值用例测试通过
2020-03-01 21:17:38,671 - [testcase_withdraw.py-->line:61] - INFO: 提现不成功-Amount大于500000用例测试通过
2020-03-01 21:17:38,814 - [testcase_withdraw.py-->line:61] - INFO: 提现不成功-Amount的小数位数多于2位用例测试通过
2020-03-01 21:17:39,123 - [testcase_withdraw.py-->line:64] - ERROR: 提现成功-Amount的小数位数1位用例测试不通过
2020-03-01 21:17:39,123 - [testcase_withdraw.py-->line:65] - ERROR: Decimal('400000.1') != Decimal('0.00')
Traceback (most recent call last):
  File "D:\untitled\withdraw_interface\testcase\testcase_withdraw.py", line 57, in testcase_withdraw
    self.assertEqual(Decimal(str(data['amount'])),(leave_amount_start-leave_amount_end))
  File "D:\python36\lib\unittest\case.py", line 820, in assertEqual
    assertion_func(first, second, msg=msg)
  File "D:\python36\lib\unittest\case.py", line 813, in _baseAssertEqual
    raise self.failureException(msg)
AssertionError: Decimal('400000.1') != Decimal('0.00')
2020-03-01 21:17:39,416 - [testcase_withdraw.py-->line:64] - ERROR: 提现成功-Amount的小数位数2位用例测试不通过
2020-03-01 21:17:39,416 - [testcase_withdraw.py-->line:65] - ERROR: Decimal('400000.09') != Decimal('0.00')
Traceback (most recent call last):
  File "D:\untitled\withdraw_interface\testcase\testcase_withdraw.py", line 57, in testcase_withdraw
    self.assertEqual(Decimal(str(data['amount'])),(leave_amount_start-leave_amount_end))
  File "D:\python36\lib\unittest\case.py", line 820, in assertEqual
    assertion_func(first, second, msg=msg)
  File "D:\python36\lib\unittest\case.py", line 813, in _baseAssertEqual
    raise self.failureException(msg)
AssertionError: Decimal('400000.09') != Decimal('0.00')
2020-03-01 21:21:05,621 - [testcase_add.py-->line:61] - INFO: 登录用例测试通过
2020-03-01 21:21:05,926 - [testcase_add.py-->line:61] - INFO: 添加成功用例测试通过
2020-03-01 21:21:06,080 - [testcase_add.py-->line:61] - INFO: 添加成功_借款期限类型2用例测试通过
2020-03-01 21:21:06,208 - [testcase_add.py-->line:64] - ERROR: 添加不成功_标题为int用例测试不通过
2020-03-01 21:21:06,208 - [testcase_add.py-->line:65] - ERROR: 2 != 0
Traceback (most recent call last):
  File "D:\untitled\withdraw_interface\testcase\testcase_add.py", line 58, in testcase_add
    self.assertEqual(expected['code'],res_info['code'])
  File "D:\python36\lib\unittest\case.py", line 820, in assertEqual
    assertion_func(first, second, msg=msg)
  File "D:\python36\lib\unittest\case.py", line 813, in _baseAssertEqual
    raise self.failureException(msg)
AssertionError: 2 != 0
2020-03-01 21:21:06,335 - [testcase_add.py-->line:64] - ERROR: 添加不成功_借款金额str用例测试不通过
2020-03-01 21:21:06,335 - [testcase_add.py-->line:65] - ERROR: 'OK' != 'JSON parse error: Cannot deserialize valu[365 chars]t"])'
- OK
+ JSON parse error: Cannot deserialize value of type `java.lang.Double` from String "strstr": not a valid Double value; nested exception is com.fasterxml.jackson.databind.exc.InvalidFormatException: Cannot deserialize value of type `java.lang.Double` from String "strstr": not a valid Double value
 at [Source: (PushbackInputStream); line: 1, column: 33] (through reference chain: com.lemon.pojo.Loan["amount"])
Traceback (most recent call last):
  File "D:\untitled\withdraw_interface\testcase\testcase_add.py", line 59, in testcase_add
    self.assertEqual(expected['msg'],res_info['msg'])
  File "D:\python36\lib\unittest\case.py", line 820, in assertEqual
    assertion_func(first, second, msg=msg)
  File "D:\python36\lib\unittest\case.py", line 1193, in assertMultiLineEqual
    self.fail(self._formatMessage(msg, standardMsg))
  File "D:\python36\lib\unittest\case.py", line 665, in fail
    raise self.failureException(msg)
AssertionError: 'OK' != 'JSON parse error: Cannot deserialize valu[365 chars]t"])'
- OK
+ JSON parse error: Cannot deserialize value of type `java.lang.Double` from String "strstr": not a valid Double value; nested exception is com.fasterxml.jackson.databind.exc.InvalidFormatException: Cannot deserialize value of type `java.lang.Double` from String "strstr": not a valid Double value
 at [Source: (PushbackInputStream); line: 1, column: 33] (through reference chain: com.lemon.pojo.Loan["amount"])

2020-03-01 21:21:06,478 - [testcase_add.py-->line:64] - ERROR: 添加不成功_年利率str用例测试不通过
2020-03-01 21:21:06,478 - [testcase_add.py-->line:65] - ERROR: 'OK' != 'JSON parse error: Cannot deserialize valu[362 chars]e"])'
- OK
+ JSON parse error: Cannot deserialize value of type `java.lang.Double` from String "年利率": not a valid Double value; nested exception is com.fasterxml.jackson.databind.exc.InvalidFormatException: Cannot deserialize value of type `java.lang.Double` from String "年利率": not a valid Double value
 at [Source: (PushbackInputStream); line: 1, column: 15] (through reference chain: com.lemon.pojo.Loan["loan_rate"])
Traceback (most recent call last):
  File "D:\untitled\withdraw_interface\testcase\testcase_add.py", line 59, in testcase_add
    self.assertEqual(expected['msg'],res_info['msg'])
  File "D:\python36\lib\unittest\case.py", line 820, in assertEqual
    assertion_func(first, second, msg=msg)
  File "D:\python36\lib\unittest\case.py", line 1193, in assertMultiLineEqual
    self.fail(self._formatMessage(msg, standardMsg))
  File "D:\python36\lib\unittest\case.py", line 665, in fail
    raise self.failureException(msg)
AssertionError: 'OK' != 'JSON parse error: Cannot deserialize valu[362 chars]e"])'
- OK
+ JSON parse error: Cannot deserialize value of type `java.lang.Double` from String "年利率": not a valid Double value; nested exception is com.fasterxml.jackson.databind.exc.InvalidFormatException: Cannot deserialize value of type `java.lang.Double` from String "年利率": not a valid Double value
 at [Source: (PushbackInputStream); line: 1, column: 15] (through reference chain: com.lemon.pojo.Loan["loan_rate"])

2020-03-01 21:21:06,630 - [testcase_add.py-->line:64] - ERROR: 添加不成功_借款期限str用例测试不通过
2020-03-01 21:21:06,630 - [testcase_add.py-->line:65] - ERROR: 2 != 0
Traceback (most recent call last):
  File "D:\untitled\withdraw_interface\testcase\testcase_add.py", line 58, in testcase_add
    self.assertEqual(expected['code'],res_info['code'])
  File "D:\python36\lib\unittest\case.py", line 820, in assertEqual
    assertion_func(first, second, msg=msg)
  File "D:\python36\lib\unittest\case.py", line 813, in _baseAssertEqual
    raise self.failureException(msg)
AssertionError: 2 != 0
2020-03-01 21:21:06,753 - [testcase_add.py-->line:61] - INFO: 添加不成功_借款期限类型非1或2用例测试通过
2020-03-01 21:21:06,875 - [testcase_add.py-->line:61] - INFO: 添加不成功_竞标天数非法用例测试通过
2020-03-01 21:21:09,600 - [testcase_audit.py-->line:87] - INFO: 登录用例测试通过
2020-03-01 21:21:16,108 - [testcase_invest.py-->line:98] - INFO: 登录用例测试通过
2020-03-01 21:21:19,127 - [testcase_withdraw.py-->line:61] - INFO: 登录用例测试通过
2020-03-01 21:21:19,434 - [testcase_withdraw.py-->line:64] - ERROR: 提现成功用例测试不通过
2020-03-01 21:21:19,434 - [testcase_withdraw.py-->line:65] - ERROR: Decimal('10000') != Decimal('0.00')
Traceback (most recent call last):
  File "D:\untitled\withdraw_interface\testcase\testcase_withdraw.py", line 57, in testcase_withdraw
    self.assertEqual(Decimal(str(data['amount'])),(leave_amount_start-leave_amount_end))
  File "D:\python36\lib\unittest\case.py", line 820, in assertEqual
    assertion_func(first, second, msg=msg)
  File "D:\python36\lib\unittest\case.py", line 813, in _baseAssertEqual
    raise self.failureException(msg)
AssertionError: Decimal('10000') != Decimal('0.00')
2020-03-01 21:21:19,556 - [testcase_withdraw.py-->line:61] - INFO: 提现不成功-MemberId为空用例测试通过
2020-03-01 21:21:19,678 - [testcase_withdraw.py-->line:61] - INFO: 提现不成功-Amount为空用例测试通过
2020-03-01 21:21:19,802 - [testcase_withdraw.py-->line:61] - INFO: 提现不成功-Amount为负值用例测试通过
2020-03-01 21:21:19,929 - [testcase_withdraw.py-->line:61] - INFO: 提现不成功-Amount大于500000用例测试通过
2020-03-01 21:21:20,054 - [testcase_withdraw.py-->line:61] - INFO: 提现不成功-Amount的小数位数多于2位用例测试通过
2020-03-01 21:21:20,367 - [testcase_withdraw.py-->line:64] - ERROR: 提现成功-Amount的小数位数1位用例测试不通过
2020-03-01 21:21:20,367 - [testcase_withdraw.py-->line:65] - ERROR: Decimal('400000.1') != Decimal('0.00')
Traceback (most recent call last):
  File "D:\untitled\withdraw_interface\testcase\testcase_withdraw.py", line 57, in testcase_withdraw
    self.assertEqual(Decimal(str(data['amount'])),(leave_amount_start-leave_amount_end))
  File "D:\python36\lib\unittest\case.py", line 820, in assertEqual
    assertion_func(first, second, msg=msg)
  File "D:\python36\lib\unittest\case.py", line 813, in _baseAssertEqual
    raise self.failureException(msg)
AssertionError: Decimal('400000.1') != Decimal('0.00')
2020-03-01 21:21:20,671 - [testcase_withdraw.py-->line:64] - ERROR: 提现成功-Amount的小数位数2位用例测试不通过
2020-03-01 21:21:20,671 - [testcase_withdraw.py-->line:65] - ERROR: Decimal('400000.09') != Decimal('0.00')
Traceback (most recent call last):
  File "D:\untitled\withdraw_interface\testcase\testcase_withdraw.py", line 57, in testcase_withdraw
    self.assertEqual(Decimal(str(data['amount'])),(leave_amount_start-leave_amount_end))
  File "D:\python36\lib\unittest\case.py", line 820, in assertEqual
    assertion_func(first, second, msg=msg)
  File "D:\python36\lib\unittest\case.py", line 813, in _baseAssertEqual
    raise self.failureException(msg)
AssertionError: Decimal('400000.09') != Decimal('0.00')
2020-03-01 21:34:38,127 - [testcase_withdraw.py-->line:61] - INFO: 登录用例测试通过
2020-03-01 21:34:38,441 - [testcase_withdraw.py-->line:64] - ERROR: 提现成功用例测试不通过
2020-03-01 21:34:38,441 - [testcase_withdraw.py-->line:65] - ERROR: Decimal('10000') != Decimal('0.00')
Traceback (most recent call last):
  File "D:\untitled\withdraw_interface\testcase\testcase_withdraw.py", line 57, in testcase_withdraw
    self.assertEqual(Decimal(str(data['amount'])),(leave_amount_start-leave_amount_end))
  File "D:\python36\lib\unittest\case.py", line 820, in assertEqual
    assertion_func(first, second, msg=msg)
  File "D:\python36\lib\unittest\case.py", line 813, in _baseAssertEqual
    raise self.failureException(msg)
AssertionError: Decimal('10000') != Decimal('0.00')
2020-03-01 21:34:38,580 - [testcase_withdraw.py-->line:61] - INFO: 提现不成功-MemberId为空用例测试通过
2020-03-01 21:34:38,718 - [testcase_withdraw.py-->line:61] - INFO: 提现不成功-Amount为空用例测试通过
2020-03-01 21:34:38,843 - [testcase_withdraw.py-->line:61] - INFO: 提现不成功-Amount为负值用例测试通过
2020-03-01 21:34:38,969 - [testcase_withdraw.py-->line:61] - INFO: 提现不成功-Amount大于500000用例测试通过
2020-03-01 21:34:39,095 - [testcase_withdraw.py-->line:61] - INFO: 提现不成功-Amount的小数位数多于2位用例测试通过
2020-03-01 21:34:39,385 - [testcase_withdraw.py-->line:64] - ERROR: 提现成功-Amount的小数位数1位用例测试不通过
2020-03-01 21:34:39,385 - [testcase_withdraw.py-->line:65] - ERROR: Decimal('400000.1') != Decimal('0.00')
Traceback (most recent call last):
  File "D:\untitled\withdraw_interface\testcase\testcase_withdraw.py", line 57, in testcase_withdraw
    self.assertEqual(Decimal(str(data['amount'])),(leave_amount_start-leave_amount_end))
  File "D:\python36\lib\unittest\case.py", line 820, in assertEqual
    assertion_func(first, second, msg=msg)
  File "D:\python36\lib\unittest\case.py", line 813, in _baseAssertEqual
    raise self.failureException(msg)
AssertionError: Decimal('400000.1') != Decimal('0.00')
2020-03-01 21:34:39,687 - [testcase_withdraw.py-->line:64] - ERROR: 提现成功-Amount的小数位数2位用例测试不通过
2020-03-01 21:34:39,687 - [testcase_withdraw.py-->line:65] - ERROR: Decimal('400000.09') != Decimal('0.00')
Traceback (most recent call last):
  File "D:\untitled\withdraw_interface\testcase\testcase_withdraw.py", line 57, in testcase_withdraw
    self.assertEqual(Decimal(str(data['amount'])),(leave_amount_start-leave_amount_end))
  File "D:\python36\lib\unittest\case.py", line 820, in assertEqual
    assertion_func(first, second, msg=msg)
  File "D:\python36\lib\unittest\case.py", line 813, in _baseAssertEqual
    raise self.failureException(msg)
AssertionError: Decimal('400000.09') != Decimal('0.00')
2020-03-01 21:34:59,631 - [testcase_invest.py-->line:98] - INFO: 登录用例测试通过
2020-03-01 21:36:01,982 - [testcase_invest.py-->line:98] - INFO: 登录用例测试通过
2020-03-01 21:39:08,622 - [testcase_invest.py-->line:98] - INFO: 登录用例测试通过
2020-03-01 21:52:41,143 - [testcase_audit.py-->line:87] - INFO: 登录用例测试通过
2020-03-01 21:54:35,125 - [testcase_audit.py-->line:87] - INFO: 登录用例测试通过
2020-03-01 21:54:44,103 - [testcase_audit.py-->line:90] - ERROR: 审核通过用例测试不通过
2020-03-01 21:54:44,103 - [testcase_audit.py-->line:91] - ERROR: 0 != 1003
Traceback (most recent call last):
  File "D:\untitled\withdraw_interface\testcase\testcase_audit.py", line 84, in testcase_audit
    self.assertEqual(expected['code'],res_info['code'])
  File "D:\python36\lib\unittest\case.py", line 820, in assertEqual
    assertion_func(first, second, msg=msg)
  File "D:\python36\lib\unittest\case.py", line 813, in _baseAssertEqual
    raise self.failureException(msg)
AssertionError: 0 != 1003
2020-03-01 21:54:50,111 - [testcase_audit.py-->line:90] - ERROR: 审核不通过用例测试不通过
2020-03-01 21:54:50,111 - [testcase_audit.py-->line:91] - ERROR: 0 != 1003
Traceback (most recent call last):
  File "D:\untitled\withdraw_interface\testcase\testcase_audit.py", line 84, in testcase_audit
    self.assertEqual(expected['code'],res_info['code'])
  File "D:\python36\lib\unittest\case.py", line 820, in assertEqual
    assertion_func(first, second, msg=msg)
  File "D:\python36\lib\unittest\case.py", line 813, in _baseAssertEqual
    raise self.failureException(msg)
AssertionError: 0 != 1003
2020-03-01 21:55:02,101 - [testcase_audit.py-->line:90] - ERROR: 项目不待审核状态用例测试不通过
2020-03-01 21:55:02,101 - [testcase_audit.py-->line:91] - ERROR: 0 != 1003
Traceback (most recent call last):
  File "D:\untitled\withdraw_interface\testcase\testcase_audit.py", line 84, in testcase_audit
    self.assertEqual(expected['code'],res_info['code'])
  File "D:\python36\lib\unittest\case.py", line 820, in assertEqual
    assertion_func(first, second, msg=msg)
  File "D:\python36\lib\unittest\case.py", line 813, in _baseAssertEqual
    raise self.failureException(msg)
AssertionError: 0 != 1003
2020-03-01 21:55:11,111 - [testcase_audit.py-->line:90] - ERROR: 参数approved_or_not非法用例测试不通过
2020-03-01 21:55:11,111 - [testcase_audit.py-->line:91] - ERROR: 1004 != 1003
Traceback (most recent call last):
  File "D:\untitled\withdraw_interface\testcase\testcase_audit.py", line 84, in testcase_audit
    self.assertEqual(expected['code'],res_info['code'])
  File "D:\python36\lib\unittest\case.py", line 820, in assertEqual
    assertion_func(first, second, msg=msg)
  File "D:\python36\lib\unittest\case.py", line 813, in _baseAssertEqual
    raise self.failureException(msg)
AssertionError: 1004 != 1003
2020-03-01 21:55:20,111 - [testcase_audit.py-->line:90] - ERROR: 项目为空用例测试不通过
2020-03-01 21:55:20,111 - [testcase_audit.py-->line:91] - ERROR: 1004 != 1003
Traceback (most recent call last):
  File "D:\untitled\withdraw_interface\testcase\testcase_audit.py", line 84, in testcase_audit
    self.assertEqual(expected['code'],res_info['code'])
  File "D:\python36\lib\unittest\case.py", line 820, in assertEqual
    assertion_func(first, second, msg=msg)
  File "D:\python36\lib\unittest\case.py", line 813, in _baseAssertEqual
    raise self.failureException(msg)
AssertionError: 1004 != 1003
2020-03-01 21:55:28,318 - [testcase_audit.py-->line:90] - ERROR: 项目不存在用例测试不通过
2020-03-01 21:55:28,318 - [testcase_audit.py-->line:91] - ERROR: 1004 != 1003
Traceback (most recent call last):
  File "D:\untitled\withdraw_interface\testcase\testcase_audit.py", line 84, in testcase_audit
    self.assertEqual(expected['code'],res_info['code'])
  File "D:\python36\lib\unittest\case.py", line 820, in assertEqual
    assertion_func(first, second, msg=msg)
  File "D:\python36\lib\unittest\case.py", line 813, in _baseAssertEqual
    raise self.failureException(msg)
AssertionError: 1004 != 1003
2020-03-01 22:00:35,843 - [testcase_audit.py-->line:88] - INFO: 登录用例测试通过
2020-03-01 22:00:43,611 - [testcase_audit.py-->line:91] - ERROR: 审核通过用例测试不通过
2020-03-01 22:00:43,611 - [testcase_audit.py-->line:92] - ERROR: 0 != 1003
Traceback (most recent call last):
  File "D:\untitled\withdraw_interface\testcase\testcase_audit.py", line 85, in testcase_audit
    self.assertEqual(expected['code'],res_info['code'])
  File "D:\python36\lib\unittest\case.py", line 820, in assertEqual
    assertion_func(first, second, msg=msg)
  File "D:\python36\lib\unittest\case.py", line 813, in _baseAssertEqual
    raise self.failureException(msg)
AssertionError: 0 != 1003
2020-03-01 22:00:52,634 - [testcase_audit.py-->line:91] - ERROR: 审核不通过用例测试不通过
2020-03-01 22:00:52,634 - [testcase_audit.py-->line:92] - ERROR: 0 != 1003
Traceback (most recent call last):
  File "D:\untitled\withdraw_interface\testcase\testcase_audit.py", line 85, in testcase_audit
    self.assertEqual(expected['code'],res_info['code'])
  File "D:\python36\lib\unittest\case.py", line 820, in assertEqual
    assertion_func(first, second, msg=msg)
  File "D:\python36\lib\unittest\case.py", line 813, in _baseAssertEqual
    raise self.failureException(msg)
AssertionError: 0 != 1003
2020-03-01 22:01:04,609 - [testcase_audit.py-->line:91] - ERROR: 项目不待审核状态用例测试不通过
2020-03-01 22:01:04,609 - [testcase_audit.py-->line:92] - ERROR: 0 != 1003
Traceback (most recent call last):
  File "D:\untitled\withdraw_interface\testcase\testcase_audit.py", line 85, in testcase_audit
    self.assertEqual(expected['code'],res_info['code'])
  File "D:\python36\lib\unittest\case.py", line 820, in assertEqual
    assertion_func(first, second, msg=msg)
  File "D:\python36\lib\unittest\case.py", line 813, in _baseAssertEqual
    raise self.failureException(msg)
AssertionError: 0 != 1003
2020-03-01 22:01:13,590 - [testcase_audit.py-->line:91] - ERROR: 参数approved_or_not非法用例测试不通过
2020-03-01 22:01:13,590 - [testcase_audit.py-->line:92] - ERROR: 1004 != 1003
Traceback (most recent call last):
  File "D:\untitled\withdraw_interface\testcase\testcase_audit.py", line 85, in testcase_audit
    self.assertEqual(expected['code'],res_info['code'])
  File "D:\python36\lib\unittest\case.py", line 820, in assertEqual
    assertion_func(first, second, msg=msg)
  File "D:\python36\lib\unittest\case.py", line 813, in _baseAssertEqual
    raise self.failureException(msg)
AssertionError: 1004 != 1003
2020-03-01 22:01:22,613 - [testcase_audit.py-->line:91] - ERROR: 项目为空用例测试不通过
2020-03-01 22:01:22,613 - [testcase_audit.py-->line:92] - ERROR: 1004 != 1003
Traceback (most recent call last):
  File "D:\untitled\withdraw_interface\testcase\testcase_audit.py", line 85, in testcase_audit
    self.assertEqual(expected['code'],res_info['code'])
  File "D:\python36\lib\unittest\case.py", line 820, in assertEqual
    assertion_func(first, second, msg=msg)
  File "D:\python36\lib\unittest\case.py", line 813, in _baseAssertEqual
    raise self.failureException(msg)
AssertionError: 1004 != 1003
2020-03-01 22:01:31,614 - [testcase_audit.py-->line:91] - ERROR: 项目不存在用例测试不通过
2020-03-01 22:01:31,615 - [testcase_audit.py-->line:92] - ERROR: 1004 != 1003
Traceback (most recent call last):
  File "D:\untitled\withdraw_interface\testcase\testcase_audit.py", line 85, in testcase_audit
    self.assertEqual(expected['code'],res_info['code'])
  File "D:\python36\lib\unittest\case.py", line 820, in assertEqual
    assertion_func(first, second, msg=msg)
  File "D:\python36\lib\unittest\case.py", line 813, in _baseAssertEqual
    raise self.failureException(msg)
AssertionError: 1004 != 1003
2020-03-01 22:08:21,101 - [testcase_audit.py-->line:93] - INFO: 登录用例测试通过
2020-03-01 22:08:27,115 - [testcase_audit.py-->line:93] - INFO: 审核通过用例测试通过
2020-03-01 22:08:34,408 - [testcase_audit.py-->line:93] - INFO: 审核不通过用例测试通过
2020-03-01 22:08:45,114 - [testcase_audit.py-->line:96] - ERROR: 项目不待审核状态用例测试不通过
2020-03-01 22:08:45,114 - [testcase_audit.py-->line:97] - ERROR: 0 != 1003
Traceback (most recent call last):
  File "D:\untitled\withdraw_interface\testcase\testcase_audit.py", line 90, in testcase_audit
    self.assertEqual(expected['code'],res_info['code'])
  File "D:\python36\lib\unittest\case.py", line 820, in assertEqual
    assertion_func(first, second, msg=msg)
  File "D:\python36\lib\unittest\case.py", line 813, in _baseAssertEqual
    raise self.failureException(msg)
AssertionError: 0 != 1003
2020-03-01 22:08:54,126 - [testcase_audit.py-->line:96] - ERROR: 参数approved_or_not非法用例测试不通过
2020-03-01 22:08:54,126 - [testcase_audit.py-->line:97] - ERROR: 1004 != 1
Traceback (most recent call last):
  File "D:\untitled\withdraw_interface\testcase\testcase_audit.py", line 90, in testcase_audit
    self.assertEqual(expected['code'],res_info['code'])
  File "D:\python36\lib\unittest\case.py", line 820, in assertEqual
    assertion_func(first, second, msg=msg)
  File "D:\python36\lib\unittest\case.py", line 813, in _baseAssertEqual
    raise self.failureException(msg)
AssertionError: 1004 != 1
2020-03-01 22:09:03,125 - [testcase_audit.py-->line:96] - ERROR: 项目为空用例测试不通过
2020-03-01 22:09:03,125 - [testcase_audit.py-->line:97] - ERROR: 1004 != 2
Traceback (most recent call last):
  File "D:\untitled\withdraw_interface\testcase\testcase_audit.py", line 90, in testcase_audit
    self.assertEqual(expected['code'],res_info['code'])
  File "D:\python36\lib\unittest\case.py", line 820, in assertEqual
    assertion_func(first, second, msg=msg)
  File "D:\python36\lib\unittest\case.py", line 813, in _baseAssertEqual
    raise self.failureException(msg)
AssertionError: 1004 != 2
2020-03-01 22:09:09,119 - [testcase_audit.py-->line:96] - ERROR: 项目不存在用例测试不通过
2020-03-01 22:09:09,119 - [testcase_audit.py-->line:97] - ERROR: 1004 != 0
Traceback (most recent call last):
  File "D:\untitled\withdraw_interface\testcase\testcase_audit.py", line 90, in testcase_audit
    self.assertEqual(expected['code'],res_info['code'])
  File "D:\python36\lib\unittest\case.py", line 820, in assertEqual
    assertion_func(first, second, msg=msg)
  File "D:\python36\lib\unittest\case.py", line 813, in _baseAssertEqual
    raise self.failureException(msg)
AssertionError: 1004 != 0
2020-03-01 22:11:42,780 - [testcase_audit.py-->line:95] - INFO: 登录用例测试通过
2020-03-01 22:11:48,563 - [testcase_audit.py-->line:95] - INFO: 审核通过用例测试通过
2020-03-01 22:11:57,620 - [testcase_audit.py-->line:95] - INFO: 审核不通过用例测试通过
2020-03-01 22:12:09,611 - [testcase_audit.py-->line:98] - ERROR: 项目不待审核状态用例测试不通过
2020-03-01 22:12:09,611 - [testcase_audit.py-->line:99] - ERROR: 0 != 1003
Traceback (most recent call last):
  File "D:\untitled\withdraw_interface\testcase\testcase_audit.py", line 92, in testcase_audit
    self.assertEqual(expected['code'],res_info['code'])
  File "D:\python36\lib\unittest\case.py", line 820, in assertEqual
    assertion_func(first, second, msg=msg)
  File "D:\python36\lib\unittest\case.py", line 813, in _baseAssertEqual
    raise self.failureException(msg)
AssertionError: 0 != 1003
2020-03-01 22:12:18,618 - [testcase_audit.py-->line:98] - ERROR: 参数approved_or_not非法用例测试不通过
2020-03-01 22:12:18,618 - [testcase_audit.py-->line:99] - ERROR: 1004 != 1
Traceback (most recent call last):
  File "D:\untitled\withdraw_interface\testcase\testcase_audit.py", line 92, in testcase_audit
    self.assertEqual(expected['code'],res_info['code'])
  File "D:\python36\lib\unittest\case.py", line 820, in assertEqual
    assertion_func(first, second, msg=msg)
  File "D:\python36\lib\unittest\case.py", line 813, in _baseAssertEqual
    raise self.failureException(msg)
AssertionError: 1004 != 1
2020-03-01 22:12:26,647 - [testcase_audit.py-->line:98] - ERROR: 项目为空用例测试不通过
2020-03-01 22:12:26,647 - [testcase_audit.py-->line:99] - ERROR: 1004 != 2
Traceback (most recent call last):
  File "D:\untitled\withdraw_interface\testcase\testcase_audit.py", line 92, in testcase_audit
    self.assertEqual(expected['code'],res_info['code'])
  File "D:\python36\lib\unittest\case.py", line 820, in assertEqual
    assertion_func(first, second, msg=msg)
  File "D:\python36\lib\unittest\case.py", line 813, in _baseAssertEqual
    raise self.failureException(msg)
AssertionError: 1004 != 2
2020-03-01 22:12:31,762 - [testcase_audit.py-->line:98] - ERROR: 项目不存在用例测试不通过
2020-03-01 22:12:31,762 - [testcase_audit.py-->line:99] - ERROR: 1004 != 2
Traceback (most recent call last):
  File "D:\untitled\withdraw_interface\testcase\testcase_audit.py", line 92, in testcase_audit
    self.assertEqual(expected['code'],res_info['code'])
  File "D:\python36\lib\unittest\case.py", line 820, in assertEqual
    assertion_func(first, second, msg=msg)
  File "D:\python36\lib\unittest\case.py", line 813, in _baseAssertEqual
    raise self.failureException(msg)
AssertionError: 1004 != 2
2020-03-01 22:16:28,619 - [testcase_audit.py-->line:95] - INFO: 登录用例测试通过
2020-03-01 22:17:37,914 - [testcase_audit.py-->line:95] - INFO: 登录用例测试通过
2020-03-01 22:17:45,115 - [testcase_audit.py-->line:95] - INFO: 审核通过用例测试通过
2020-03-01 22:17:54,140 - [testcase_audit.py-->line:95] - INFO: 审核不通过用例测试通过
2020-03-01 22:18:06,115 - [testcase_audit.py-->line:98] - ERROR: 项目不待审核状态用例测试不通过
2020-03-01 22:18:06,115 - [testcase_audit.py-->line:99] - ERROR: 0 != 2
Traceback (most recent call last):
  File "D:\untitled\withdraw_interface\testcase\testcase_audit.py", line 92, in testcase_audit
    self.assertEqual(expected['code'],res_info['code'])
  File "D:\python36\lib\unittest\case.py", line 820, in assertEqual
    assertion_func(first, second, msg=msg)
  File "D:\python36\lib\unittest\case.py", line 813, in _baseAssertEqual
    raise self.failureException(msg)
AssertionError: 0 != 2
2020-03-01 22:18:14,728 - [testcase_audit.py-->line:98] - ERROR: 参数approved_or_not非法用例测试不通过
2020-03-01 22:18:14,728 - [testcase_audit.py-->line:99] - ERROR: 1004 != 1
Traceback (most recent call last):
  File "D:\untitled\withdraw_interface\testcase\testcase_audit.py", line 92, in testcase_audit
    self.assertEqual(expected['code'],res_info['code'])
  File "D:\python36\lib\unittest\case.py", line 820, in assertEqual
    assertion_func(first, second, msg=msg)
  File "D:\python36\lib\unittest\case.py", line 813, in _baseAssertEqual
    raise self.failureException(msg)
AssertionError: 1004 != 1
2020-03-01 22:18:21,603 - [testcase_audit.py-->line:98] - ERROR: 项目为空用例测试不通过
2020-03-01 22:18:21,603 - [testcase_audit.py-->line:99] - ERROR: 1004 != 2
Traceback (most recent call last):
  File "D:\untitled\withdraw_interface\testcase\testcase_audit.py", line 92, in testcase_audit
    self.assertEqual(expected['code'],res_info['code'])
  File "D:\python36\lib\unittest\case.py", line 820, in assertEqual
    assertion_func(first, second, msg=msg)
  File "D:\python36\lib\unittest\case.py", line 813, in _baseAssertEqual
    raise self.failureException(msg)
AssertionError: 1004 != 2
2020-03-01 22:18:30,613 - [testcase_audit.py-->line:98] - ERROR: 项目不存在用例测试不通过
2020-03-01 22:18:30,613 - [testcase_audit.py-->line:99] - ERROR: 1004 != 2
Traceback (most recent call last):
  File "D:\untitled\withdraw_interface\testcase\testcase_audit.py", line 92, in testcase_audit
    self.assertEqual(expected['code'],res_info['code'])
  File "D:\python36\lib\unittest\case.py", line 820, in assertEqual
    assertion_func(first, second, msg=msg)
  File "D:\python36\lib\unittest\case.py", line 813, in _baseAssertEqual
    raise self.failureException(msg)
AssertionError: 1004 != 2
2020-03-01 22:25:28,712 - [testcase_invest.py-->line:102] - INFO: 登录用例测试通过
2020-03-01 22:25:30,631 - [testcase_invest.py-->line:105] - ERROR: 投资不通过_投资项目非竞标状态用例测试不通过
2020-03-01 22:25:30,631 - [testcase_invest.py-->line:106] - ERROR: 1004 != 2
Traceback (most recent call last):
  File "D:\untitled\withdraw_interface\testcase\testcase_invest.py", line 99, in test_invest
    self.assertEqual(expected['code'],res_info['code'])
  File "D:\python36\lib\unittest\case.py", line 820, in assertEqual
    assertion_func(first, second, msg=msg)
  File "D:\python36\lib\unittest\case.py", line 813, in _baseAssertEqual
    raise self.failureException(msg)
AssertionError: 1004 != 2
2020-03-01 22:25:36,659 - [testcase_invest.py-->line:105] - ERROR: 投资通过用例测试不通过
2020-03-01 22:25:36,659 - [testcase_invest.py-->line:106] - ERROR: 0 != 2
Traceback (most recent call last):
  File "D:\untitled\withdraw_interface\testcase\testcase_invest.py", line 99, in test_invest
    self.assertEqual(expected['code'],res_info['code'])
  File "D:\python36\lib\unittest\case.py", line 820, in assertEqual
    assertion_func(first, second, msg=msg)
  File "D:\python36\lib\unittest\case.py", line 813, in _baseAssertEqual
    raise self.failureException(msg)
AssertionError: 0 != 2
2020-03-01 22:25:39,636 - [testcase_invest.py-->line:105] - ERROR: 投资不通过_投资费非100整数用例测试不通过
2020-03-01 22:25:39,636 - [testcase_invest.py-->line:106] - ERROR: 0 != 2
Traceback (most recent call last):
  File "D:\untitled\withdraw_interface\testcase\testcase_invest.py", line 99, in test_invest
    self.assertEqual(expected['code'],res_info['code'])
  File "D:\python36\lib\unittest\case.py", line 820, in assertEqual
    assertion_func(first, second, msg=msg)
  File "D:\python36\lib\unittest\case.py", line 813, in _baseAssertEqual
    raise self.failureException(msg)
AssertionError: 0 != 2
2020-03-01 22:25:42,614 - [testcase_invest.py-->line:105] - ERROR: 投资不通过_投资费大于项目费用用例测试不通过
2020-03-01 22:25:42,615 - [testcase_invest.py-->line:106] - ERROR: 0 != 2
Traceback (most recent call last):
  File "D:\untitled\withdraw_interface\testcase\testcase_invest.py", line 99, in test_invest
    self.assertEqual(expected['code'],res_info['code'])
  File "D:\python36\lib\unittest\case.py", line 820, in assertEqual
    assertion_func(first, second, msg=msg)
  File "D:\python36\lib\unittest\case.py", line 813, in _baseAssertEqual
    raise self.failureException(msg)
AssertionError: 0 != 2
2020-03-01 22:25:45,622 - [testcase_invest.py-->line:105] - ERROR: 投资不通过用例测试不通过
2020-03-01 22:25:45,622 - [testcase_invest.py-->line:106] - ERROR: 1004 != 2
Traceback (most recent call last):
  File "D:\untitled\withdraw_interface\testcase\testcase_invest.py", line 99, in test_invest
    self.assertEqual(expected['code'],res_info['code'])
  File "D:\python36\lib\unittest\case.py", line 820, in assertEqual
    assertion_func(first, second, msg=msg)
  File "D:\python36\lib\unittest\case.py", line 813, in _baseAssertEqual
    raise self.failureException(msg)
AssertionError: 1004 != 2
2020-03-01 22:25:48,611 - [testcase_invest.py-->line:105] - ERROR: 投资不通过用例测试不通过
2020-03-01 22:25:48,612 - [testcase_invest.py-->line:106] - ERROR: 1004 != 2
Traceback (most recent call last):
  File "D:\untitled\withdraw_interface\testcase\testcase_invest.py", line 99, in test_invest
    self.assertEqual(expected['code'],res_info['code'])
  File "D:\python36\lib\unittest\case.py", line 820, in assertEqual
    assertion_func(first, second, msg=msg)
  File "D:\python36\lib\unittest\case.py", line 813, in _baseAssertEqual
    raise self.failureException(msg)
AssertionError: 1004 != 2
2020-03-01 22:30:17,123 - [testcase_invest.py-->line:102] - INFO: 登录用例测试通过
2020-03-01 22:30:20,113 - [testcase_invest.py-->line:105] - ERROR: 投资不通过_投资项目非竞标状态用例测试不通过
2020-03-01 22:30:20,113 - [testcase_invest.py-->line:106] - ERROR: 1004 != 2
Traceback (most recent call last):
  File "D:\untitled\withdraw_interface\testcase\testcase_invest.py", line 99, in test_invest
    self.assertEqual(expected['code'],res_info['code'])
  File "D:\python36\lib\unittest\case.py", line 820, in assertEqual
    assertion_func(first, second, msg=msg)
  File "D:\python36\lib\unittest\case.py", line 813, in _baseAssertEqual
    raise self.failureException(msg)
AssertionError: 1004 != 2
2020-03-01 22:30:26,124 - [testcase_invest.py-->line:105] - ERROR: 投资通过用例测试不通过
2020-03-01 22:30:26,125 - [testcase_invest.py-->line:106] - ERROR: 0 != 2
Traceback (most recent call last):
  File "D:\untitled\withdraw_interface\testcase\testcase_invest.py", line 99, in test_invest
    self.assertEqual(expected['code'],res_info['code'])
  File "D:\python36\lib\unittest\case.py", line 820, in assertEqual
    assertion_func(first, second, msg=msg)
  File "D:\python36\lib\unittest\case.py", line 813, in _baseAssertEqual
    raise self.failureException(msg)
AssertionError: 0 != 2
2020-03-01 22:30:29,120 - [testcase_invest.py-->line:105] - ERROR: 投资不通过_投资费非100整数用例测试不通过
2020-03-01 22:30:29,120 - [testcase_invest.py-->line:106] - ERROR: 0 != 2
Traceback (most recent call last):
  File "D:\untitled\withdraw_interface\testcase\testcase_invest.py", line 99, in test_invest
    self.assertEqual(expected['code'],res_info['code'])
  File "D:\python36\lib\unittest\case.py", line 820, in assertEqual
    assertion_func(first, second, msg=msg)
  File "D:\python36\lib\unittest\case.py", line 813, in _baseAssertEqual
    raise self.failureException(msg)
AssertionError: 0 != 2
2020-03-01 22:30:32,123 - [testcase_invest.py-->line:105] - ERROR: 投资不通过_投资费大于项目费用用例测试不通过
2020-03-01 22:30:32,124 - [testcase_invest.py-->line:106] - ERROR: 0 != 2
Traceback (most recent call last):
  File "D:\untitled\withdraw_interface\testcase\testcase_invest.py", line 99, in test_invest
    self.assertEqual(expected['code'],res_info['code'])
  File "D:\python36\lib\unittest\case.py", line 820, in assertEqual
    assertion_func(first, second, msg=msg)
  File "D:\python36\lib\unittest\case.py", line 813, in _baseAssertEqual
    raise self.failureException(msg)
AssertionError: 0 != 2
2020-03-01 22:30:35,100 - [testcase_invest.py-->line:105] - ERROR: 投资不通过用例测试不通过
2020-03-01 22:30:35,100 - [testcase_invest.py-->line:106] - ERROR: 1004 != 2
Traceback (most recent call last):
  File "D:\untitled\withdraw_interface\testcase\testcase_invest.py", line 99, in test_invest
    self.assertEqual(expected['code'],res_info['code'])
  File "D:\python36\lib\unittest\case.py", line 820, in assertEqual
    assertion_func(first, second, msg=msg)
  File "D:\python36\lib\unittest\case.py", line 813, in _baseAssertEqual
    raise self.failureException(msg)
AssertionError: 1004 != 2
2020-03-01 22:30:38,245 - [testcase_invest.py-->line:105] - ERROR: 投资不通过用例测试不通过
2020-03-01 22:30:38,246 - [testcase_invest.py-->line:106] - ERROR: 1004 != 2
Traceback (most recent call last):
  File "D:\untitled\withdraw_interface\testcase\testcase_invest.py", line 99, in test_invest
    self.assertEqual(expected['code'],res_info['code'])
  File "D:\python36\lib\unittest\case.py", line 820, in assertEqual
    assertion_func(first, second, msg=msg)
  File "D:\python36\lib\unittest\case.py", line 813, in _baseAssertEqual
    raise self.failureException(msg)
AssertionError: 1004 != 2
2020-03-01 22:34:49,735 - [testcase_invest.py-->line:103] - INFO: 登录用例测试通过
2020-03-01 22:34:51,596 - [testcase_invest.py-->line:106] - ERROR: 投资不通过_投资项目非竞标状态用例测试不通过
2020-03-01 22:34:51,596 - [testcase_invest.py-->line:107] - ERROR: 1004 != 2
Traceback (most recent call last):
  File "D:\untitled\withdraw_interface\testcase\testcase_invest.py", line 100, in test_invest
    self.assertEqual(expected['code'],res_info['code'])
  File "D:\python36\lib\unittest\case.py", line 820, in assertEqual
    assertion_func(first, second, msg=msg)
  File "D:\python36\lib\unittest\case.py", line 813, in _baseAssertEqual
    raise self.failureException(msg)
AssertionError: 1004 != 2
2020-03-01 22:34:57,646 - [testcase_invest.py-->line:103] - INFO: 投资通过用例测试通过
2020-03-01 22:35:00,611 - [testcase_invest.py-->line:106] - ERROR: 投资不通过_投资费非100整数用例测试不通过
2020-03-01 22:35:00,611 - [testcase_invest.py-->line:107] - ERROR: 0 != 2
Traceback (most recent call last):
  File "D:\untitled\withdraw_interface\testcase\testcase_invest.py", line 100, in test_invest
    self.assertEqual(expected['code'],res_info['code'])
  File "D:\python36\lib\unittest\case.py", line 820, in assertEqual
    assertion_func(first, second, msg=msg)
  File "D:\python36\lib\unittest\case.py", line 813, in _baseAssertEqual
    raise self.failureException(msg)
AssertionError: 0 != 2
2020-03-01 22:35:03,633 - [testcase_invest.py-->line:106] - ERROR: 投资不通过_投资费大于项目费用用例测试不通过
2020-03-01 22:35:03,634 - [testcase_invest.py-->line:107] - ERROR: 0 != 2
Traceback (most recent call last):
  File "D:\untitled\withdraw_interface\testcase\testcase_invest.py", line 100, in test_invest
    self.assertEqual(expected['code'],res_info['code'])
  File "D:\python36\lib\unittest\case.py", line 820, in assertEqual
    assertion_func(first, second, msg=msg)
  File "D:\python36\lib\unittest\case.py", line 813, in _baseAssertEqual
    raise self.failureException(msg)
AssertionError: 0 != 2
2020-03-01 22:35:06,603 - [testcase_invest.py-->line:106] - ERROR: 投资不通过用例测试不通过
2020-03-01 22:35:06,603 - [testcase_invest.py-->line:107] - ERROR: 1004 != 2
Traceback (most recent call last):
  File "D:\untitled\withdraw_interface\testcase\testcase_invest.py", line 100, in test_invest
    self.assertEqual(expected['code'],res_info['code'])
  File "D:\python36\lib\unittest\case.py", line 820, in assertEqual
    assertion_func(first, second, msg=msg)
  File "D:\python36\lib\unittest\case.py", line 813, in _baseAssertEqual
    raise self.failureException(msg)
AssertionError: 1004 != 2
2020-03-01 22:35:09,628 - [testcase_invest.py-->line:106] - ERROR: 投资不通过用例测试不通过
2020-03-01 22:35:09,628 - [testcase_invest.py-->line:107] - ERROR: 1004 != 2
Traceback (most recent call last):
  File "D:\untitled\withdraw_interface\testcase\testcase_invest.py", line 100, in test_invest
    self.assertEqual(expected['code'],res_info['code'])
  File "D:\python36\lib\unittest\case.py", line 820, in assertEqual
    assertion_func(first, second, msg=msg)
  File "D:\python36\lib\unittest\case.py", line 813, in _baseAssertEqual
    raise self.failureException(msg)
AssertionError: 1004 != 2
2020-03-01 22:41:57,119 - [testcase_invest.py-->line:103] - INFO: 登录用例测试通过
2020-03-01 22:41:58,328 - [testcase_invest.py-->line:103] - INFO: 投资不通过_投资项目非竞标状态用例测试通过
2020-03-01 22:42:01,597 - [testcase_invest.py-->line:103] - INFO: 投资通过用例测试通过
2020-03-01 22:42:03,113 - [testcase_invest.py-->line:103] - INFO: 投资不通过_投资费非100整数用例测试通过
2020-03-01 22:42:06,116 - [testcase_invest.py-->line:103] - INFO: 投资不通过_投资费大于项目费用用例测试通过
2020-03-01 22:42:09,124 - [testcase_invest.py-->line:103] - INFO: 投资不通过用例测试通过
2020-03-01 22:42:12,085 - [testcase_invest.py-->line:103] - INFO: 投资不通过用例测试通过
2020-03-01 22:42:33,343 - [testcase_audit.py-->line:96] - INFO: 登录用例测试通过
2020-03-01 22:42:40,617 - [testcase_audit.py-->line:96] - INFO: 审核通过用例测试通过
2020-03-01 22:42:49,617 - [testcase_audit.py-->line:96] - INFO: 审核不通过用例测试通过
2020-03-01 22:42:59,122 - [testcase_audit.py-->line:99] - ERROR: 项目不待审核状态用例测试不通过
2020-03-01 22:42:59,122 - [testcase_audit.py-->line:100] - ERROR: 0 != 2
Traceback (most recent call last):
  File "D:\untitled\withdraw_interface\testcase\testcase_audit.py", line 93, in testcase_audit
    self.assertEqual(expected['code'],res_info['code'])
  File "D:\python36\lib\unittest\case.py", line 820, in assertEqual
    assertion_func(first, second, msg=msg)
  File "D:\python36\lib\unittest\case.py", line 813, in _baseAssertEqual
    raise self.failureException(msg)
AssertionError: 0 != 2
2020-03-01 22:43:08,123 - [testcase_audit.py-->line:99] - ERROR: 参数approved_or_not非法用例测试不通过
2020-03-01 22:43:08,123 - [testcase_audit.py-->line:100] - ERROR: 1004 != 1
Traceback (most recent call last):
  File "D:\untitled\withdraw_interface\testcase\testcase_audit.py", line 93, in testcase_audit
    self.assertEqual(expected['code'],res_info['code'])
  File "D:\python36\lib\unittest\case.py", line 820, in assertEqual
    assertion_func(first, second, msg=msg)
  File "D:\python36\lib\unittest\case.py", line 813, in _baseAssertEqual
    raise self.failureException(msg)
AssertionError: 1004 != 1
2020-03-01 22:43:14,119 - [testcase_audit.py-->line:99] - ERROR: 项目为空用例测试不通过
2020-03-01 22:43:14,119 - [testcase_audit.py-->line:100] - ERROR: 1004 != 2
Traceback (most recent call last):
  File "D:\untitled\withdraw_interface\testcase\testcase_audit.py", line 93, in testcase_audit
    self.assertEqual(expected['code'],res_info['code'])
  File "D:\python36\lib\unittest\case.py", line 820, in assertEqual
    assertion_func(first, second, msg=msg)
  File "D:\python36\lib\unittest\case.py", line 813, in _baseAssertEqual
    raise self.failureException(msg)
AssertionError: 1004 != 2
2020-03-01 22:43:23,124 - [testcase_audit.py-->line:99] - ERROR: 项目不存在用例测试不通过
2020-03-01 22:43:23,124 - [testcase_audit.py-->line:100] - ERROR: 1004 != 2
Traceback (most recent call last):
  File "D:\untitled\withdraw_interface\testcase\testcase_audit.py", line 93, in testcase_audit
    self.assertEqual(expected['code'],res_info['code'])
  File "D:\python36\lib\unittest\case.py", line 820, in assertEqual
    assertion_func(first, second, msg=msg)
  File "D:\python36\lib\unittest\case.py", line 813, in _baseAssertEqual
    raise self.failureException(msg)
AssertionError: 1004 != 2
2020-03-01 22:47:01,800 - [testcase_audit.py-->line:96] - INFO: 登录用例测试通过
2020-03-01 22:47:09,117 - [testcase_audit.py-->line:96] - INFO: 审核通过用例测试通过
2020-03-01 22:47:14,295 - [testcase_audit.py-->line:96] - INFO: 审核不通过用例测试通过
2020-03-01 22:47:18,777 - [testcase_audit.py-->line:96] - INFO: 项目不待审核状态用例测试通过
2020-03-01 22:47:22,163 - [testcase_audit.py-->line:96] - INFO: 参数approved_or_not非法用例测试通过
2020-03-01 22:47:25,552 - [testcase_audit.py-->line:96] - INFO: 项目为空用例测试通过
2020-03-01 22:48:43,637 - [testcase_audit.py-->line:96] - INFO: 登录用例测试通过
2020-03-01 22:48:52,688 - [testcase_audit.py-->line:96] - INFO: 审核通过用例测试通过
2020-03-01 22:48:58,615 - [testcase_audit.py-->line:96] - INFO: 审核不通过用例测试通过
2020-03-01 22:49:10,615 - [testcase_audit.py-->line:96] - INFO: 项目不待审核状态用例测试通过
2020-03-01 22:49:19,625 - [testcase_audit.py-->line:96] - INFO: 参数approved_or_not非法用例测试通过
2020-03-01 22:49:28,639 - [testcase_audit.py-->line:96] - INFO: 项目为空用例测试通过
2020-03-01 22:49:36,483 - [testcase_audit.py-->line:96] - INFO: 项目不存在用例测试通过
2020-03-01 22:49:55,619 - [testcase_add.py-->line:61] - INFO: 登录用例测试通过
2020-03-01 22:49:58,701 - [testcase_add.py-->line:61] - INFO: 添加成功用例测试通过
2020-03-01 22:50:01,615 - [testcase_add.py-->line:61] - INFO: 添加成功_借款期限类型2用例测试通过
2020-03-01 22:50:04,620 - [testcase_add.py-->line:64] - ERROR: 添加不成功_标题为int用例测试不通过
2020-03-01 22:50:04,620 - [testcase_add.py-->line:65] - ERROR: 2 != 0
Traceback (most recent call last):
  File "D:\untitled\withdraw_interface\testcase\testcase_add.py", line 58, in testcase_add
    self.assertEqual(expected['code'],res_info['code'])
  File "D:\python36\lib\unittest\case.py", line 820, in assertEqual
    assertion_func(first, second, msg=msg)
  File "D:\python36\lib\unittest\case.py", line 813, in _baseAssertEqual
    raise self.failureException(msg)
AssertionError: 2 != 0
2020-03-01 22:50:07,619 - [testcase_add.py-->line:64] - ERROR: 添加不成功_借款金额str用例测试不通过
2020-03-01 22:50:07,619 - [testcase_add.py-->line:65] - ERROR: 'OK' != 'JSON parse error: Cannot deserialize valu[365 chars]t"])'
- OK
+ JSON parse error: Cannot deserialize value of type `java.lang.Double` from String "strstr": not a valid Double value; nested exception is com.fasterxml.jackson.databind.exc.InvalidFormatException: Cannot deserialize value of type `java.lang.Double` from String "strstr": not a valid Double value
 at [Source: (PushbackInputStream); line: 1, column: 12] (through reference chain: com.lemon.pojo.Loan["amount"])
Traceback (most recent call last):
  File "D:\untitled\withdraw_interface\testcase\testcase_add.py", line 59, in testcase_add
    self.assertEqual(expected['msg'],res_info['msg'])
  File "D:\python36\lib\unittest\case.py", line 820, in assertEqual
    assertion_func(first, second, msg=msg)
  File "D:\python36\lib\unittest\case.py", line 1193, in assertMultiLineEqual
    self.fail(self._formatMessage(msg, standardMsg))
  File "D:\python36\lib\unittest\case.py", line 665, in fail
    raise self.failureException(msg)
AssertionError: 'OK' != 'JSON parse error: Cannot deserialize valu[365 chars]t"])'
- OK
+ JSON parse error: Cannot deserialize value of type `java.lang.Double` from String "strstr": not a valid Double value; nested exception is com.fasterxml.jackson.databind.exc.InvalidFormatException: Cannot deserialize value of type `java.lang.Double` from String "strstr": not a valid Double value
 at [Source: (PushbackInputStream); line: 1, column: 12] (through reference chain: com.lemon.pojo.Loan["amount"])

2020-03-01 22:50:10,630 - [testcase_add.py-->line:64] - ERROR: 添加不成功_年利率str用例测试不通过
2020-03-01 22:50:10,630 - [testcase_add.py-->line:65] - ERROR: 'OK' != 'JSON parse error: Cannot deserialize valu[363 chars]e"])'
- OK
+ JSON parse error: Cannot deserialize value of type `java.lang.Double` from String "年利率": not a valid Double value; nested exception is com.fasterxml.jackson.databind.exc.InvalidFormatException: Cannot deserialize value of type `java.lang.Double` from String "年利率": not a valid Double value
 at [Source: (PushbackInputStream); line: 1, column: 118] (through reference chain: com.lemon.pojo.Loan["loan_rate"])
Traceback (most recent call last):
  File "D:\untitled\withdraw_interface\testcase\testcase_add.py", line 59, in testcase_add
    self.assertEqual(expected['msg'],res_info['msg'])
  File "D:\python36\lib\unittest\case.py", line 820, in assertEqual
    assertion_func(first, second, msg=msg)
  File "D:\python36\lib\unittest\case.py", line 1193, in assertMultiLineEqual
    self.fail(self._formatMessage(msg, standardMsg))
  File "D:\python36\lib\unittest\case.py", line 665, in fail
    raise self.failureException(msg)
AssertionError: 'OK' != 'JSON parse error: Cannot deserialize valu[363 chars]e"])'
- OK
+ JSON parse error: Cannot deserialize value of type `java.lang.Double` from String "年利率": not a valid Double value; nested exception is com.fasterxml.jackson.databind.exc.InvalidFormatException: Cannot deserialize value of type `java.lang.Double` from String "年利率": not a valid Double value
 at [Source: (PushbackInputStream); line: 1, column: 118] (through reference chain: com.lemon.pojo.Loan["loan_rate"])

2020-03-01 22:50:13,618 - [testcase_add.py-->line:64] - ERROR: 添加不成功_借款期限str用例测试不通过
2020-03-01 22:50:13,618 - [testcase_add.py-->line:65] - ERROR: 2 != 0
Traceback (most recent call last):
  File "D:\untitled\withdraw_interface\testcase\testcase_add.py", line 58, in testcase_add
    self.assertEqual(expected['code'],res_info['code'])
  File "D:\python36\lib\unittest\case.py", line 820, in assertEqual
    assertion_func(first, second, msg=msg)
  File "D:\python36\lib\unittest\case.py", line 813, in _baseAssertEqual
    raise self.failureException(msg)
AssertionError: 2 != 0
2020-03-01 22:50:16,616 - [testcase_add.py-->line:61] - INFO: 添加不成功_借款期限类型非1或2用例测试通过
2020-03-01 22:50:17,814 - [testcase_add.py-->line:61] - INFO: 添加不成功_竞标天数非法用例测试通过
2020-03-01 22:50:25,619 - [testcase_audit.py-->line:96] - INFO: 登录用例测试通过
2020-03-01 22:50:34,618 - [testcase_audit.py-->line:99] - ERROR: 审核通过用例测试不通过
2020-03-01 22:50:34,618 - [testcase_audit.py-->line:100] - ERROR: 0 != 2
Traceback (most recent call last):
  File "D:\untitled\withdraw_interface\testcase\testcase_audit.py", line 93, in testcase_audit
    self.assertEqual(expected['code'],res_info['code'])
  File "D:\python36\lib\unittest\case.py", line 820, in assertEqual
    assertion_func(first, second, msg=msg)
  File "D:\python36\lib\unittest\case.py", line 813, in _baseAssertEqual
    raise self.failureException(msg)
AssertionError: 0 != 2
2020-03-01 22:50:43,616 - [testcase_audit.py-->line:96] - INFO: 审核不通过用例测试通过
2020-03-01 22:50:55,615 - [testcase_audit.py-->line:96] - INFO: 项目不待审核状态用例测试通过
2020-03-01 22:51:01,615 - [testcase_audit.py-->line:96] - INFO: 参数approved_or_not非法用例测试通过
2020-03-01 22:51:10,613 - [testcase_audit.py-->line:96] - INFO: 项目为空用例测试通过
2020-03-01 22:51:19,613 - [testcase_audit.py-->line:96] - INFO: 项目不存在用例测试通过
2020-03-01 22:51:28,617 - [testcase_invest.py-->line:103] - INFO: 登录用例测试通过
2020-03-01 22:51:31,613 - [testcase_invest.py-->line:103] - INFO: 投资不通过_投资项目非竞标状态用例测试通过
2020-03-01 22:51:37,620 - [testcase_invest.py-->line:103] - INFO: 投资通过用例测试通过
2020-03-01 22:51:38,815 - [testcase_invest.py-->line:103] - INFO: 投资不通过_投资费非100整数用例测试通过
2020-03-01 22:51:40,596 - [testcase_invest.py-->line:103] - INFO: 投资不通过_投资费大于项目费用用例测试通过
2020-03-01 22:51:41,785 - [testcase_invest.py-->line:103] - INFO: 投资不通过用例测试通过
2020-03-01 22:51:43,614 - [testcase_invest.py-->line:103] - INFO: 投资不通过用例测试通过
2020-03-01 22:51:46,616 - [testcase_withdraw.py-->line:61] - INFO: 登录用例测试通过
2020-03-01 22:51:49,743 - [testcase_withdraw.py-->line:64] - ERROR: 提现成功用例测试不通过
2020-03-01 22:51:49,743 - [testcase_withdraw.py-->line:65] - ERROR: Decimal('10000') != Decimal('0.00')
Traceback (most recent call last):
  File "D:\untitled\withdraw_interface\testcase\testcase_withdraw.py", line 57, in testcase_withdraw
    self.assertEqual(Decimal(str(data['amount'])),(leave_amount_start-leave_amount_end))
  File "D:\python36\lib\unittest\case.py", line 820, in assertEqual
    assertion_func(first, second, msg=msg)
  File "D:\python36\lib\unittest\case.py", line 813, in _baseAssertEqual
    raise self.failureException(msg)
AssertionError: Decimal('10000') != Decimal('0.00')
2020-03-01 22:51:52,614 - [testcase_withdraw.py-->line:61] - INFO: 提现不成功-MemberId为空用例测试通过
2020-03-01 22:51:55,614 - [testcase_withdraw.py-->line:61] - INFO: 提现不成功-Amount为空用例测试通过
2020-03-01 22:51:58,636 - [testcase_withdraw.py-->line:61] - INFO: 提现不成功-Amount为负值用例测试通过
2020-03-01 22:52:00,375 - [testcase_withdraw.py-->line:61] - INFO: 提现不成功-Amount大于500000用例测试通过
2020-03-01 22:52:01,625 - [testcase_withdraw.py-->line:61] - INFO: 提现不成功-Amount的小数位数多于2位用例测试通过
2020-03-01 22:52:04,695 - [testcase_withdraw.py-->line:64] - ERROR: 提现成功-Amount的小数位数1位用例测试不通过
2020-03-01 22:52:04,695 - [testcase_withdraw.py-->line:65] - ERROR: Decimal('400000.1') != Decimal('0.00')
Traceback (most recent call last):
  File "D:\untitled\withdraw_interface\testcase\testcase_withdraw.py", line 57, in testcase_withdraw
    self.assertEqual(Decimal(str(data['amount'])),(leave_amount_start-leave_amount_end))
  File "D:\python36\lib\unittest\case.py", line 820, in assertEqual
    assertion_func(first, second, msg=msg)
  File "D:\python36\lib\unittest\case.py", line 813, in _baseAssertEqual
    raise self.failureException(msg)
AssertionError: Decimal('400000.1') != Decimal('0.00')
2020-03-01 22:52:07,691 - [testcase_withdraw.py-->line:64] - ERROR: 提现成功-Amount的小数位数2位用例测试不通过
2020-03-01 22:52:07,691 - [testcase_withdraw.py-->line:65] - ERROR: Decimal('400000.09') != Decimal('0.00')
Traceback (most recent call last):
  File "D:\untitled\withdraw_interface\testcase\testcase_withdraw.py", line 57, in testcase_withdraw
    self.assertEqual(Decimal(str(data['amount'])),(leave_amount_start-leave_amount_end))
  File "D:\python36\lib\unittest\case.py", line 820, in assertEqual
    assertion_func(first, second, msg=msg)
  File "D:\python36\lib\unittest\case.py", line 813, in _baseAssertEqual
    raise self.failureException(msg)
AssertionError: Decimal('400000.09') != Decimal('0.00')
2020-03-01 22:56:29,605 - [testcase_audit.py-->line:96] - INFO: 登录用例测试通过
2020-03-01 22:56:38,622 - [testcase_audit.py-->line:96] - INFO: 审核通过用例测试通过
2020-03-01 22:56:44,608 - [testcase_audit.py-->line:96] - INFO: 审核不通过用例测试通过
2020-03-01 22:56:54,739 - [testcase_audit.py-->line:96] - INFO: 项目不待审核状态用例测试通过
2020-03-01 22:57:01,615 - [testcase_audit.py-->line:96] - INFO: 参数approved_or_not非法用例测试通过
2020-03-01 22:57:08,626 - [testcase_audit.py-->line:96] - INFO: 项目为空用例测试通过
2020-03-01 22:57:17,621 - [testcase_audit.py-->line:96] - INFO: 项目不存在用例测试通过
2020-03-02 08:37:25,838 - [testcase_audit.py-->line:97] - INFO: 审核通过用例测试通过
2020-03-02 08:37:34,625 - [testcase_audit.py-->line:97] - INFO: 审核不通过用例测试通过
2020-03-02 08:37:50,110 - [testcase_audit.py-->line:97] - INFO: 参数approved_or_not非法用例测试通过
2020-03-02 08:37:59,120 - [testcase_audit.py-->line:97] - INFO: 项目为空用例测试通过
2020-03-02 08:38:07,342 - [testcase_audit.py-->line:97] - INFO: 项目不存在用例测试通过
2020-03-02 08:38:49,610 - [testcase_audit.py-->line:97] - INFO: 审核通过用例测试通过
2020-03-02 08:38:58,616 - [testcase_audit.py-->line:97] - INFO: 审核不通过用例测试通过
2020-03-02 08:39:08,160 - [testcase_audit.py-->line:97] - INFO: 项目不待审核状态用例测试通过
2020-03-02 08:39:17,155 - [testcase_audit.py-->line:97] - INFO: 参数approved_or_not非法用例测试通过
2020-03-02 08:39:26,120 - [testcase_audit.py-->line:97] - INFO: 项目为空用例测试通过
2020-03-02 08:39:35,120 - [testcase_audit.py-->line:97] - INFO: 项目不存在用例测试通过
2020-03-02 08:39:56,624 - [testcase_audit.py-->line:97] - INFO: 登录用例测试通过
2020-03-02 08:40:03,744 - [testcase_audit.py-->line:97] - INFO: 审核通过用例测试通过
2020-03-02 08:40:11,644 - [testcase_audit.py-->line:97] - INFO: 审核不通过用例测试通过
2020-03-02 08:40:23,606 - [testcase_audit.py-->line:97] - INFO: 项目不待审核状态用例测试通过
2020-03-02 08:40:30,545 - [testcase_audit.py-->line:97] - INFO: 参数approved_or_not非法用例测试通过
2020-03-02 08:40:39,618 - [testcase_audit.py-->line:97] - INFO: 项目为空用例测试通过
2020-03-02 08:40:48,629 - [testcase_audit.py-->line:97] - INFO: 项目不存在用例测试通过
2020-03-02 08:46:15,622 - [testcase_invest.py-->line:98] - INFO: 登录用例测试通过
2020-03-02 08:46:18,626 - [testcase_invest.py-->line:98] - INFO: 投资通过用例测试通过
2020-03-02 08:46:21,633 - [testcase_invest.py-->line:98] - INFO: 投资不通过_投资费非100整数用例测试通过
2020-03-02 08:46:22,838 - [testcase_invest.py-->line:98] - INFO: 投资不通过_投资费大于项目费用用例测试通过
2020-03-02 08:46:24,611 - [testcase_invest.py-->line:98] - INFO: 投资不通过用例测试通过
2020-03-02 08:46:27,620 - [testcase_invest.py-->line:98] - INFO: 投资不通过用例测试通过
2020-03-02 08:48:37,626 - [testcase_invest.py-->line:98] - INFO: 登录用例测试通过
2020-03-02 08:48:40,434 - [testcase_invest.py-->line:98] - INFO: 投资不通过_投资项目非竞标状态用例测试通过
2020-03-02 08:48:46,620 - [testcase_invest.py-->line:98] - INFO: 投资通过用例测试通过
2020-03-02 08:48:49,612 - [testcase_invest.py-->line:98] - INFO: 投资不通过_投资费非100整数用例测试通过
2020-03-02 08:48:52,616 - [testcase_invest.py-->line:98] - INFO: 投资不通过_投资费大于项目费用用例测试通过
2020-03-02 08:48:55,615 - [testcase_invest.py-->line:98] - INFO: 投资不通过用例测试通过
2020-03-02 08:48:58,622 - [testcase_invest.py-->line:98] - INFO: 投资不通过用例测试通过
2020-03-02 08:59:14,642 - [testcase_invest.py-->line:102] - INFO: 登录用例测试通过
2020-03-02 09:00:05,610 - [testcase_invest.py-->line:102] - INFO: 登录用例测试通过
2020-03-02 09:00:08,615 - [testcase_invest.py-->line:102] - INFO: 投资不通过_投资项目非竞标状态用例测试通过
2020-03-02 09:00:14,634 - [testcase_invest.py-->line:102] - INFO: 投资通过用例测试通过
2020-03-02 09:00:17,643 - [testcase_invest.py-->line:102] - INFO: 投资不通过_投资费非100整数用例测试通过
2020-03-02 09:00:20,617 - [testcase_invest.py-->line:102] - INFO: 投资不通过_投资费大于项目费用用例测试通过
2020-03-02 09:00:23,622 - [testcase_invest.py-->line:102] - INFO: 投资不通过用例测试通过
2020-03-02 09:00:26,607 - [testcase_invest.py-->line:102] - INFO: 投资不通过用例测试通过
2020-03-02 09:02:13,653 - [testcase_audit.py-->line:91] - INFO: 登录用例测试通过
2020-03-02 09:02:22,616 - [testcase_audit.py-->line:91] - INFO: 审核通过用例测试通过
2020-03-02 09:02:31,386 - [testcase_audit.py-->line:91] - INFO: 审核不通过用例测试通过
2020-03-02 09:02:39,150 - [testcase_audit.py-->line:91] - INFO: 项目不待审核状态用例测试通过
2020-03-02 09:02:48,129 - [testcase_audit.py-->line:91] - INFO: 参数approved_or_not非法用例测试通过
2020-03-02 09:02:57,137 - [testcase_audit.py-->line:91] - INFO: 项目为空用例测试通过
2020-03-02 09:03:05,408 - [testcase_audit.py-->line:91] - INFO: 项目不存在用例测试通过
2020-03-02 09:04:19,120 - [testcase_add.py-->line:61] - INFO: 登录用例测试通过
2020-03-02 09:04:22,195 - [testcase_add.py-->line:61] - INFO: 添加成功用例测试通过
2020-03-02 09:04:23,401 - [testcase_add.py-->line:61] - INFO: 添加成功_借款期限类型2用例测试通过
2020-03-02 09:04:25,111 - [testcase_add.py-->line:64] - ERROR: 添加不成功_标题为int用例测试不通过
2020-03-02 09:04:25,111 - [testcase_add.py-->line:65] - ERROR: 2 != 0
Traceback (most recent call last):
  File "D:\untitled\withdraw_interface\testcase\testcase_add.py", line 58, in testcase_add
    self.assertEqual(expected['code'],res_info['code'])
  File "D:\python36\lib\unittest\case.py", line 820, in assertEqual
    assertion_func(first, second, msg=msg)
  File "D:\python36\lib\unittest\case.py", line 813, in _baseAssertEqual
    raise self.failureException(msg)
AssertionError: 2 != 0
2020-03-02 09:04:28,121 - [testcase_add.py-->line:64] - ERROR: 添加不成功_借款金额str用例测试不通过
2020-03-02 09:04:28,121 - [testcase_add.py-->line:65] - ERROR: 'OK' != 'JSON parse error: Cannot deserialize valu[365 chars]t"])'
- OK
+ JSON parse error: Cannot deserialize value of type `java.lang.Double` from String "strstr": not a valid Double value; nested exception is com.fasterxml.jackson.databind.exc.InvalidFormatException: Cannot deserialize value of type `java.lang.Double` from String "strstr": not a valid Double value
 at [Source: (PushbackInputStream); line: 1, column: 50] (through reference chain: com.lemon.pojo.Loan["amount"])
Traceback (most recent call last):
  File "D:\untitled\withdraw_interface\testcase\testcase_add.py", line 59, in testcase_add
    self.assertEqual(expected['msg'],res_info['msg'])
  File "D:\python36\lib\unittest\case.py", line 820, in assertEqual
    assertion_func(first, second, msg=msg)
  File "D:\python36\lib\unittest\case.py", line 1193, in assertMultiLineEqual
    self.fail(self._formatMessage(msg, standardMsg))
  File "D:\python36\lib\unittest\case.py", line 665, in fail
    raise self.failureException(msg)
AssertionError: 'OK' != 'JSON parse error: Cannot deserialize valu[365 chars]t"])'
- OK
+ JSON parse error: Cannot deserialize value of type `java.lang.Double` from String "strstr": not a valid Double value; nested exception is com.fasterxml.jackson.databind.exc.InvalidFormatException: Cannot deserialize value of type `java.lang.Double` from String "strstr": not a valid Double value
 at [Source: (PushbackInputStream); line: 1, column: 50] (through reference chain: com.lemon.pojo.Loan["amount"])

2020-03-02 09:04:31,122 - [testcase_add.py-->line:64] - ERROR: 添加不成功_年利率str用例测试不通过
2020-03-02 09:04:31,122 - [testcase_add.py-->line:65] - ERROR: 'OK' != 'JSON parse error: Cannot deserialize valu[362 chars]e"])'
- OK
+ JSON parse error: Cannot deserialize value of type `java.lang.Double` from String "年利率": not a valid Double value; nested exception is com.fasterxml.jackson.databind.exc.InvalidFormatException: Cannot deserialize value of type `java.lang.Double` from String "年利率": not a valid Double value
 at [Source: (PushbackInputStream); line: 1, column: 15] (through reference chain: com.lemon.pojo.Loan["loan_rate"])
Traceback (most recent call last):
  File "D:\untitled\withdraw_interface\testcase\testcase_add.py", line 59, in testcase_add
    self.assertEqual(expected['msg'],res_info['msg'])
  File "D:\python36\lib\unittest\case.py", line 820, in assertEqual
    assertion_func(first, second, msg=msg)
  File "D:\python36\lib\unittest\case.py", line 1193, in assertMultiLineEqual
    self.fail(self._formatMessage(msg, standardMsg))
  File "D:\python36\lib\unittest\case.py", line 665, in fail
    raise self.failureException(msg)
AssertionError: 'OK' != 'JSON parse error: Cannot deserialize valu[362 chars]e"])'
- OK
+ JSON parse error: Cannot deserialize value of type `java.lang.Double` from String "年利率": not a valid Double value; nested exception is com.fasterxml.jackson.databind.exc.InvalidFormatException: Cannot deserialize value of type `java.lang.Double` from String "年利率": not a valid Double value
 at [Source: (PushbackInputStream); line: 1, column: 15] (through reference chain: com.lemon.pojo.Loan["loan_rate"])

2020-03-02 09:04:34,154 - [testcase_add.py-->line:64] - ERROR: 添加不成功_借款期限str用例测试不通过
2020-03-02 09:04:34,154 - [testcase_add.py-->line:65] - ERROR: 2 != 0
Traceback (most recent call last):
  File "D:\untitled\withdraw_interface\testcase\testcase_add.py", line 58, in testcase_add
    self.assertEqual(expected['code'],res_info['code'])
  File "D:\python36\lib\unittest\case.py", line 820, in assertEqual
    assertion_func(first, second, msg=msg)
  File "D:\python36\lib\unittest\case.py", line 813, in _baseAssertEqual
    raise self.failureException(msg)
AssertionError: 2 != 0
2020-03-02 09:04:37,115 - [testcase_add.py-->line:61] - INFO: 添加不成功_借款期限类型非1或2用例测试通过
2020-03-02 09:04:40,124 - [testcase_add.py-->line:61] - INFO: 添加不成功_竞标天数非法用例测试通过
2020-03-02 09:04:49,124 - [testcase_audit.py-->line:91] - INFO: 登录用例测试通过
2020-03-02 09:04:58,129 - [testcase_audit.py-->line:91] - INFO: 审核通过用例测试通过
2020-03-02 09:05:06,288 - [testcase_audit.py-->line:91] - INFO: 审核不通过用例测试通过
2020-03-02 09:05:16,144 - [testcase_audit.py-->line:91] - INFO: 项目不待审核状态用例测试通过
2020-03-02 09:05:25,107 - [testcase_audit.py-->line:91] - INFO: 参数approved_or_not非法用例测试通过
2020-03-02 09:05:30,556 - [testcase_audit.py-->line:91] - INFO: 项目为空用例测试通过
2020-03-02 09:05:35,698 - [testcase_audit.py-->line:91] - INFO: 项目不存在用例测试通过
2020-03-02 09:05:43,590 - [testcase_invest.py-->line:102] - INFO: 登录用例测试通过
2020-03-02 09:05:46,292 - [testcase_invest.py-->line:102] - INFO: 投资不通过_投资项目非竞标状态用例测试通过
2020-03-02 09:05:50,138 - [testcase_invest.py-->line:102] - INFO: 投资通过用例测试通过
2020-03-02 09:05:52,397 - [testcase_invest.py-->line:102] - INFO: 投资不通过_投资费非100整数用例测试通过
2020-03-02 09:05:53,593 - [testcase_invest.py-->line:102] - INFO: 投资不通过_投资费大于项目费用用例测试通过
2020-03-02 09:05:56,602 - [testcase_invest.py-->line:102] - INFO: 投资不通过用例测试通过
2020-03-02 09:05:59,617 - [testcase_invest.py-->line:102] - INFO: 投资不通过用例测试通过
2020-03-02 09:06:02,610 - [testcase_withdraw.py-->line:61] - INFO: 登录用例测试通过
2020-03-02 09:06:04,124 - [testcase_withdraw.py-->line:64] - ERROR: 提现成功用例测试不通过
2020-03-02 09:06:04,124 - [testcase_withdraw.py-->line:65] - ERROR: Decimal('10000') != Decimal('0.00')
Traceback (most recent call last):
  File "D:\untitled\withdraw_interface\testcase\testcase_withdraw.py", line 57, in testcase_withdraw
    self.assertEqual(Decimal(str(data['amount'])),(leave_amount_start-leave_amount_end))
  File "D:\python36\lib\unittest\case.py", line 820, in assertEqual
    assertion_func(first, second, msg=msg)
  File "D:\python36\lib\unittest\case.py", line 813, in _baseAssertEqual
    raise self.failureException(msg)
AssertionError: Decimal('10000') != Decimal('0.00')
2020-03-02 09:06:05,608 - [testcase_withdraw.py-->line:61] - INFO: 提现不成功-MemberId为空用例测试通过
2020-03-02 09:06:07,575 - [testcase_withdraw.py-->line:61] - INFO: 提现不成功-Amount为空用例测试通过
2020-03-02 09:06:08,781 - [testcase_withdraw.py-->line:61] - INFO: 提现不成功-Amount为负值用例测试通过
2020-03-02 09:06:10,073 - [testcase_withdraw.py-->line:61] - INFO: 提现不成功-Amount大于500000用例测试通过
2020-03-02 09:06:11,622 - [testcase_withdraw.py-->line:61] - INFO: 提现不成功-Amount的小数位数多于2位用例测试通过
2020-03-02 09:06:14,701 - [testcase_withdraw.py-->line:64] - ERROR: 提现成功-Amount的小数位数1位用例测试不通过
2020-03-02 09:06:14,701 - [testcase_withdraw.py-->line:65] - ERROR: Decimal('400000.1') != Decimal('0.00')
Traceback (most recent call last):
  File "D:\untitled\withdraw_interface\testcase\testcase_withdraw.py", line 57, in testcase_withdraw
    self.assertEqual(Decimal(str(data['amount'])),(leave_amount_start-leave_amount_end))
  File "D:\python36\lib\unittest\case.py", line 820, in assertEqual
    assertion_func(first, second, msg=msg)
  File "D:\python36\lib\unittest\case.py", line 813, in _baseAssertEqual
    raise self.failureException(msg)
AssertionError: Decimal('400000.1') != Decimal('0.00')
2020-03-02 09:06:17,695 - [testcase_withdraw.py-->line:64] - ERROR: 提现成功-Amount的小数位数2位用例测试不通过
2020-03-02 09:06:17,696 - [testcase_withdraw.py-->line:65] - ERROR: Decimal('400000.09') != Decimal('0.00')
Traceback (most recent call last):
  File "D:\untitled\withdraw_interface\testcase\testcase_withdraw.py", line 57, in testcase_withdraw
    self.assertEqual(Decimal(str(data['amount'])),(leave_amount_start-leave_amount_end))
  File "D:\python36\lib\unittest\case.py", line 820, in assertEqual
    assertion_func(first, second, msg=msg)
  File "D:\python36\lib\unittest\case.py", line 813, in _baseAssertEqual
    raise self.failureException(msg)
AssertionError: Decimal('400000.09') != Decimal('0.00')
2020-03-06 20:57:40,541 - [testcase_add.py-->line:61] - INFO: 登录用例测试通过
2020-03-06 20:57:41,308 - [testcase_add.py-->line:61] - INFO: 添加成功用例测试通过
2020-03-06 20:57:41,599 - [testcase_add.py-->line:61] - INFO: 添加成功_借款期限类型2用例测试通过
2020-03-06 20:57:42,088 - [testcase_add.py-->line:64] - ERROR: 添加不成功_标题为int用例测试不通过
2020-03-06 20:57:42,088 - [testcase_add.py-->line:65] - ERROR: 2 != 0
Traceback (most recent call last):
  File "D:\untitled\withdraw_interface\testcase\testcase_add.py", line 58, in testcase_add
    self.assertEqual(expected['code'],res_info['code'])
  File "D:\python36\lib\unittest\case.py", line 820, in assertEqual
    assertion_func(first, second, msg=msg)
  File "D:\python36\lib\unittest\case.py", line 813, in _baseAssertEqual
    raise self.failureException(msg)
AssertionError: 2 != 0
2020-03-06 20:57:42,304 - [testcase_add.py-->line:64] - ERROR: 添加不成功_借款金额str用例测试不通过
2020-03-06 20:57:42,304 - [testcase_add.py-->line:65] - ERROR: 'OK' != 'JSON parse error: Cannot deserialize valu[365 chars]t"])'
- OK
+ JSON parse error: Cannot deserialize value of type `java.lang.Double` from String "strstr": not a valid Double value; nested exception is com.fasterxml.jackson.databind.exc.InvalidFormatException: Cannot deserialize value of type `java.lang.Double` from String "strstr": not a valid Double value
 at [Source: (PushbackInputStream); line: 1, column: 33] (through reference chain: com.lemon.pojo.Loan["amount"])
Traceback (most recent call last):
  File "D:\untitled\withdraw_interface\testcase\testcase_add.py", line 59, in testcase_add
    self.assertEqual(expected['msg'],res_info['msg'])
  File "D:\python36\lib\unittest\case.py", line 820, in assertEqual
    assertion_func(first, second, msg=msg)
  File "D:\python36\lib\unittest\case.py", line 1193, in assertMultiLineEqual
    self.fail(self._formatMessage(msg, standardMsg))
  File "D:\python36\lib\unittest\case.py", line 665, in fail
    raise self.failureException(msg)
AssertionError: 'OK' != 'JSON parse error: Cannot deserialize valu[365 chars]t"])'
- OK
+ JSON parse error: Cannot deserialize value of type `java.lang.Double` from String "strstr": not a valid Double value; nested exception is com.fasterxml.jackson.databind.exc.InvalidFormatException: Cannot deserialize value of type `java.lang.Double` from String "strstr": not a valid Double value
 at [Source: (PushbackInputStream); line: 1, column: 33] (through reference chain: com.lemon.pojo.Loan["amount"])

2020-03-06 20:57:42,522 - [testcase_add.py-->line:64] - ERROR: 添加不成功_年利率str用例测试不通过
2020-03-06 20:57:42,522 - [testcase_add.py-->line:65] - ERROR: 'OK' != 'JSON parse error: Cannot deserialize valu[362 chars]e"])'
- OK
+ JSON parse error: Cannot deserialize value of type `java.lang.Double` from String "年利率": not a valid Double value; nested exception is com.fasterxml.jackson.databind.exc.InvalidFormatException: Cannot deserialize value of type `java.lang.Double` from String "年利率": not a valid Double value
 at [Source: (PushbackInputStream); line: 1, column: 15] (through reference chain: com.lemon.pojo.Loan["loan_rate"])
Traceback (most recent call last):
  File "D:\untitled\withdraw_interface\testcase\testcase_add.py", line 59, in testcase_add
    self.assertEqual(expected['msg'],res_info['msg'])
  File "D:\python36\lib\unittest\case.py", line 820, in assertEqual
    assertion_func(first, second, msg=msg)
  File "D:\python36\lib\unittest\case.py", line 1193, in assertMultiLineEqual
    self.fail(self._formatMessage(msg, standardMsg))
  File "D:\python36\lib\unittest\case.py", line 665, in fail
    raise self.failureException(msg)
AssertionError: 'OK' != 'JSON parse error: Cannot deserialize valu[362 chars]e"])'
- OK
+ JSON parse error: Cannot deserialize value of type `java.lang.Double` from String "年利率": not a valid Double value; nested exception is com.fasterxml.jackson.databind.exc.InvalidFormatException: Cannot deserialize value of type `java.lang.Double` from String "年利率": not a valid Double value
 at [Source: (PushbackInputStream); line: 1, column: 15] (through reference chain: com.lemon.pojo.Loan["loan_rate"])

2020-03-06 20:57:42,713 - [testcase_add.py-->line:64] - ERROR: 添加不成功_借款期限str用例测试不通过
2020-03-06 20:57:42,713 - [testcase_add.py-->line:65] - ERROR: 2 != 0
Traceback (most recent call last):
  File "D:\untitled\withdraw_interface\testcase\testcase_add.py", line 58, in testcase_add
    self.assertEqual(expected['code'],res_info['code'])
  File "D:\python36\lib\unittest\case.py", line 820, in assertEqual
    assertion_func(first, second, msg=msg)
  File "D:\python36\lib\unittest\case.py", line 813, in _baseAssertEqual
    raise self.failureException(msg)
AssertionError: 2 != 0
2020-03-06 20:57:42,893 - [testcase_add.py-->line:61] - INFO: 添加不成功_借款期限类型非1或2用例测试通过
2020-03-06 20:57:43,078 - [testcase_add.py-->line:61] - INFO: 添加不成功_竞标天数非法用例测试通过
2020-03-06 20:57:43,461 - [testcase_audit.py-->line:91] - INFO: 登录用例测试通过
2020-03-06 20:57:43,944 - [testcase_audit.py-->line:91] - INFO: 审核通过用例测试通过
2020-03-06 20:57:44,340 - [testcase_audit.py-->line:91] - INFO: 审核不通过用例测试通过
2020-03-06 20:57:44,770 - [testcase_audit.py-->line:91] - INFO: 项目不待审核状态用例测试通过
2020-03-06 20:57:45,151 - [testcase_audit.py-->line:91] - INFO: 参数approved_or_not非法用例测试通过
2020-03-06 20:57:45,515 - [testcase_audit.py-->line:91] - INFO: 项目为空用例测试通过
2020-03-06 20:57:45,862 - [testcase_audit.py-->line:91] - INFO: 项目不存在用例测试通过
2020-03-06 20:57:46,225 - [testcase_invest.py-->line:102] - INFO: 登录用例测试通过
2020-03-06 20:57:46,410 - [testcase_invest.py-->line:102] - INFO: 投资不通过_投资项目非竞标状态用例测试通过
2020-03-06 20:57:46,837 - [testcase_invest.py-->line:102] - INFO: 投资通过用例测试通过
2020-03-06 20:57:47,098 - [testcase_invest.py-->line:102] - INFO: 投资不通过_投资费非100整数用例测试通过
2020-03-06 20:57:47,280 - [testcase_invest.py-->line:102] - INFO: 投资不通过_投资费大于项目费用用例测试通过
2020-03-06 20:57:47,470 - [testcase_invest.py-->line:102] - INFO: 投资不通过用例测试通过
2020-03-06 20:57:47,655 - [testcase_invest.py-->line:102] - INFO: 投资不通过用例测试通过
2020-03-06 20:57:47,850 - [testcase_withdraw.py-->line:61] - INFO: 登录用例测试通过
2020-03-06 20:57:48,416 - [testcase_withdraw.py-->line:64] - ERROR: 提现成功用例测试不通过
2020-03-06 20:57:48,416 - [testcase_withdraw.py-->line:65] - ERROR: Decimal('10000') != Decimal('0.00')
Traceback (most recent call last):
  File "D:\untitled\withdraw_interface\testcase\testcase_withdraw.py", line 57, in testcase_withdraw
    self.assertEqual(Decimal(str(data['amount'])),(leave_amount_start-leave_amount_end))
  File "D:\python36\lib\unittest\case.py", line 820, in assertEqual
    assertion_func(first, second, msg=msg)
  File "D:\python36\lib\unittest\case.py", line 813, in _baseAssertEqual
    raise self.failureException(msg)
AssertionError: Decimal('10000') != Decimal('0.00')
2020-03-06 20:57:48,614 - [testcase_withdraw.py-->line:61] - INFO: 提现不成功-MemberId为空用例测试通过
2020-03-06 20:57:48,803 - [testcase_withdraw.py-->line:61] - INFO: 提现不成功-Amount为空用例测试通过
2020-03-06 20:57:48,993 - [testcase_withdraw.py-->line:61] - INFO: 提现不成功-Amount为负值用例测试通过
2020-03-06 20:57:49,194 - [testcase_withdraw.py-->line:61] - INFO: 提现不成功-Amount大于500000用例测试通过
2020-03-06 20:57:49,368 - [testcase_withdraw.py-->line:61] - INFO: 提现不成功-Amount的小数位数多于2位用例测试通过
2020-03-06 20:57:49,737 - [testcase_withdraw.py-->line:64] - ERROR: 提现成功-Amount的小数位数1位用例测试不通过
2020-03-06 20:57:49,737 - [testcase_withdraw.py-->line:65] - ERROR: Decimal('400000.1') != Decimal('0.00')
Traceback (most recent call last):
  File "D:\untitled\withdraw_interface\testcase\testcase_withdraw.py", line 57, in testcase_withdraw
    self.assertEqual(Decimal(str(data['amount'])),(leave_amount_start-leave_amount_end))
  File "D:\python36\lib\unittest\case.py", line 820, in assertEqual
    assertion_func(first, second, msg=msg)
  File "D:\python36\lib\unittest\case.py", line 813, in _baseAssertEqual
    raise self.failureException(msg)
AssertionError: Decimal('400000.1') != Decimal('0.00')
2020-03-06 20:57:50,083 - [testcase_withdraw.py-->line:64] - ERROR: 提现成功-Amount的小数位数2位用例测试不通过
2020-03-06 20:57:50,083 - [testcase_withdraw.py-->line:65] - ERROR: Decimal('400000.09') != Decimal('0.00')
Traceback (most recent call last):
  File "D:\untitled\withdraw_interface\testcase\testcase_withdraw.py", line 57, in testcase_withdraw
    self.assertEqual(Decimal(str(data['amount'])),(leave_amount_start-leave_amount_end))
  File "D:\python36\lib\unittest\case.py", line 820, in assertEqual
    assertion_func(first, second, msg=msg)
  File "D:\python36\lib\unittest\case.py", line 813, in _baseAssertEqual
    raise self.failureException(msg)
AssertionError: Decimal('400000.09') != Decimal('0.00')
